Workbook

Sheet DASHBOARD
A1: لوحة متابعة التقدم في التخطيط الأسبوعي – قسم التربية الإسلامية Islamic Education Weekly Planning Progress Dashboard | R1: Week | S1: Completion
R2: 1 | S2: =TRACKER!R2 -> 0.025
A3: اسم المعلم / Teacher Name | E3: الأسبوع المحدد / Selected Week | I3: العام الأكاديمي / Academic Year | M3: نظام المتابعة / Tracking | R3: 2 | S3: =TRACKER!R3 -> 0
E4: 1 | I4: 2026–2027 | M4: مرتبط تلقائيًا بـ 30 أسبوعًا Automatically linked to 30 weeks | R4: 3 | S4: =TRACKER!R4 -> 0
R5: 4 | S5: =TRACKER!R5 -> 0
A6: الأسابيع المكتملة / Completed Weeks | E6: قيد التنفيذ / In Progress | I6: لم تبدأ / Not Started | M6: نسبة الإنجاز الكلية / Overall Completion | R6: 5 | S6: =TRACKER!R6 -> 0
A7: =COUNTIF(TRACKER!$S$2:$S$31,"مكتمل / Complete") -> 0 | E7: =COUNTIF(TRACKER!$S$2:$S$31,"قيد التنفيذ / In Progress") -> 1 | I7: =COUNTIF(TRACKER!$S$2:$S$31,"لم يبدأ / Not Started") -> 29 | M7: =AVERAGE(TRACKER!$R$2:$R$31) -> 0.00083333333 | R7: 6 | S7: =TRACKER!R7 -> 0
R8: 7 | S8: =TRACKER!R8 -> 0
R9: 8 | S9: =TRACKER!R9 -> 0
A10: البيانات الأساسية Core Planning | D10: التمايز Differentiation | G10: الحصة الأولى First Period | J10: الحصة الثانية Second Period | M10: التأمل Reflection | R10: 9 | S10: =TRACKER!R10 -> 0
A11: =SUM(TRACKER!$L$2:$L$31)/(30*17) -> 0.0019607843 | D11: =SUM(TRACKER!$M$2:$M$31)/(30*4) -> 0 | G11: =SUM(TRACKER!$N$2:$N$31)/(30*9) -> 0 | J11: =SUM(TRACKER!$O$2:$O$31)/(30*9) -> 0 | M11: =SUM(TRACKER!$P$2:$P$31)/30 -> 0 | R11: 10 | S11: =TRACKER!R11 -> 0
R12: 11 | S12: =TRACKER!R12 -> 0
R13: 12 | S13: =TRACKER!R13 -> 0
A14: ملخص الأسبوع المحدد / Selected Week Snapshot | R14: 13 | S14: =TRACKER!R14 -> 0
A15: نسبة الإنجاز / Completion | D15: الحالة / Status | G15: المتابعة التالية / Next Action | L15: عنوان الدرس / Lesson Title | R15: 14 | S15: =TRACKER!R15 -> 0
A16: =IFERROR(VLOOKUP($E$4,TRACKER!$A$2:$T$31,18,FALSE),0) -> 0.025 | D16: =IFERROR(VLOOKUP($E$4,TRACKER!$A$2:$T$31,19,FALSE),"") -> قيد التنفيذ / In Progress | G16: =IFERROR(VLOOKUP($E$4,TRACKER!$A$2:$T$31,20,FALSE),"") -> أكمل البيانات الأساسية / Complete core planning fields | L16: =IFERROR(VLOOKUP($E$4,TRACKER!$A$2:$T$31,9,FALSE),"") | R16: 15 | S16: =TRACKER!R16 -> 0
R17: 16 | S17: =TRACKER!R17 -> 0
R18: 17 | S18: =TRACKER!R18 -> 0
R19: 18 | S19: =TRACKER!R19 -> 0
A20: الأسبوع Week | B20: التاريخ Date | C20: المحور Domain | D20: الوحدة Unit | E20: عنوان الدرس Lesson Title | F20: الإنجاز Completion | G20: الحالة Status | H20: المتابعة Next Action | R20: 19 | S20: =TRACKER!R20 -> 0
A21: =TRACKER!A2 -> 1 | B21: =TRACKER!F2 | C21: =TRACKER!G2 | D21: =TRACKER!H2 | E21: =TRACKER!I2 | F21: =TRACKER!R2 -> 0.025 | G21: =TRACKER!S2 -> قيد التنفيذ / In Progress | H21: =TRACKER!T2 -> أكمل البيانات الأساسية / Complete core planning fields | R21: 20 | S21: =TRACKER!R21 -> 0
A22: =TRACKER!A3 -> 2 | B22: =TRACKER!F3 | C22: =TRACKER!G3 | D22: =TRACKER!H3 | E22: =TRACKER!I3 | F22: =TRACKER!R3 -> 0 | G22: =TRACKER!S3 -> لم يبدأ / Not Started | H22: =TRACKER!T3 -> أكمل البيانات الأساسية / Complete core planning fields | R22: 21 | S22: =TRACKER!R22 -> 0
A23: =TRACKER!A4 -> 3 | B23: =TRACKER!F4 | C23: =TRACKER!G4 | D23: =TRACKER!H4 | E23: =TRACKER!I4 | F23: =TRACKER!R4 -> 0 | G23: =TRACKER!S4 -> لم يبدأ / Not Started | H23: =TRACKER!T4 -> أكمل البيانات الأساسية / Complete core planning fields | R23: 22 | S23: =TRACKER!R23 -> 0
A24: =TRACKER!A5 -> 4 | B24: =TRACKER!F5 | C24: =TRACKER!G5 | D24: =TRACKER!H5 | E24: =TRACKER!I5 | F24: =TRACKER!R5 -> 0 | G24: =TRACKER!S5 -> لم يبدأ / Not Started | H24: =TRACKER!T5 -> أكمل البيانات الأساسية / Complete core planning fields | R24: 23 | S24: =TRACKER!R24 -> 0
A25: =TRACKER!A6 -> 5 | B25: =TRACKER!F6 | C25: =TRACKER!G6 | D25: =TRACKER!H6 | E25: =TRACKER!I6 | F25: =TRACKER!R6 -> 0 | G25: =TRACKER!S6 -> لم يبدأ / Not Started | H25: =TRACKER!T6 -> أكمل البيانات الأساسية / Complete core planning fields | R25: 24 | S25: =TRACKER!R25 -> 0
A26: =TRACKER!A7 -> 6 | B26: =TRACKER!F7 | C26: =TRACKER!G7 | D26: =TRACKER!H7 | E26: =TRACKER!I7 | F26: =TRACKER!R7 -> 0 | G26: =TRACKER!S7 -> لم يبدأ / Not Started | H26: =TRACKER!T7 -> أكمل البيانات الأساسية / Complete core planning fields | R26: 25 | S26: =TRACKER!R26 -> 0
A27: =TRACKER!A8 -> 7 | B27: =TRACKER!F8 | C27: =TRACKER!G8 | D27: =TRACKER!H8 | E27: =TRACKER!I8 | F27: =TRACKER!R8 -> 0 | G27: =TRACKER!S8 -> لم يبدأ / Not Started | H27: =TRACKER!T8 -> أكمل البيانات الأساسية / Complete core planning fields | R27: 26 | S27: =TRACKER!R27 -> 0
A28: =TRACKER!A9 -> 8 | B28: =TRACKER!F9 | C28: =TRACKER!G9 | D28: =TRACKER!H9 | E28: =TRACKER!I9 | F28: =TRACKER!R9 -> 0 | G28: =TRACKER!S9 -> لم يبدأ / Not Started | H28: =TRACKER!T9 -> أكمل البيانات الأساسية / Complete core planning fields | R28: 27 | S28: =TRACKER!R28 -> 0
A29: =TRACKER!A10 -> 9 | B29: =TRACKER!F10 | C29: =TRACKER!G10 | D29: =TRACKER!H10 | E29: =TRACKER!I10 | F29: =TRACKER!R10 -> 0 | G29: =TRACKER!S10 -> لم يبدأ / Not Started | H29: =TRACKER!T10 -> أكمل البيانات الأساسية / Complete core planning fields | R29: 28 | S29: =TRACKER!R29 -> 0
A30: =TRACKER!A11 -> 10 | B30: =TRACKER!F11 | C30: =TRACKER!G11 | D30: =TRACKER!H11 | E30: =TRACKER!I11 | F30: =TRACKER!R11 -> 0 | G30: =TRACKER!S11 -> لم يبدأ / Not Started | H30: =TRACKER!T11 -> أكمل البيانات الأساسية / Complete core planning fields | R30: 29 | S30: =TRACKER!R30 -> 0
A31: =TRACKER!A12 -> 11 | B31: =TRACKER!F12 | C31: =TRACKER!G12 | D31: =TRACKER!H12 | E31: =TRACKER!I12 | F31: =TRACKER!R12 -> 0 | G31: =TRACKER!S12 -> لم يبدأ / Not Started | H31: =TRACKER!T12 -> أكمل البيانات الأساسية / Complete core planning fields | R31: 30 | S31: =TRACKER!R31 -> 0
A32: =TRACKER!A13 -> 12 | B32: =TRACKER!F13 | C32: =TRACKER!G13 | D32: =TRACKER!H13 | E32: =TRACKER!I13 | F32: =TRACKER!R13 -> 0 | G32: =TRACKER!S13 -> لم يبدأ / Not Started | H32: =TRACKER!T13 -> أكمل البيانات الأساسية / Complete core planning fields
A33: =TRACKER!A14 -> 13 | B33: =TRACKER!F14 | C33: =TRACKER!G14 | D33: =TRACKER!H14 | E33: =TRACKER!I14 | F33: =TRACKER!R14 -> 0 | G33: =TRACKER!S14 -> لم يبدأ / Not Started | H33: =TRACKER!T14 -> أكمل البيانات الأساسية / Complete core planning fields
A34: =TRACKER!A15 -> 14 | B34: =TRACKER!F15 | C34: =TRACKER!G15 | D34: =TRACKER!H15 | E34: =TRACKER!I15 | F34: =TRACKER!R15 -> 0 | G34: =TRACKER!S15 -> لم يبدأ / Not Started | H34: =TRACKER!T15 -> أكمل البيانات الأساسية / Complete core planning fields | R34: Category | S34: Completion
A35: =TRACKER!A16 -> 15 | B35: =TRACKER!F16 | C35: =TRACKER!G16 | D35: =TRACKER!H16 | E35: =TRACKER!I16 | F35: =TRACKER!R16 -> 0 | G35: =TRACKER!S16 -> لم يبدأ / Not Started | H35: =TRACKER!T16 -> أكمل البيانات الأساسية / Complete core planning fields | R35: Core Planning | S35: =A11 -> 0.0019607843
A36: =TRACKER!A17 -> 16 | B36: =TRACKER!F17 | C36: =TRACKER!G17 | D36: =TRACKER!H17 | E36: =TRACKER!I17 | F36: =TRACKER!R17 -> 0 | G36: =TRACKER!S17 -> لم يبدأ / Not Started | H36: =TRACKER!T17 -> أكمل البيانات الأساسية / Complete core planning fields | R36: Differentiation | S36: =D11 -> 0
A37: =TRACKER!A18 -> 17 | B37: =TRACKER!F18 | C37: =TRACKER!G18 | D37: =TRACKER!H18 | E37: =TRACKER!I18 | F37: =TRACKER!R18 -> 0 | G37: =TRACKER!S18 -> لم يبدأ / Not Started | H37: =TRACKER!T18 -> أكمل البيانات الأساسية / Complete core planning fields | R37: First Period | S37: =G11 -> 0
A38: =TRACKER!A19 -> 18 | B38: =TRACKER!F19 | C38: =TRACKER!G19 | D38: =TRACKER!H19 | E38: =TRACKER!I19 | F38: =TRACKER!R19 -> 0 | G38: =TRACKER!S19 -> لم يبدأ / Not Started | H38: =TRACKER!T19 -> أكمل البيانات الأساسية / Complete core planning fields | R38: Second Period | S38: =J11 -> 0
A39: =TRACKER!A20 -> 19 | B39: =TRACKER!F20 | C39: =TRACKER!G20 | D39: =TRACKER!H20 | E39: =TRACKER!I20 | F39: =TRACKER!R20 -> 0 | G39: =TRACKER!S20 -> لم يبدأ / Not Started | H39: =TRACKER!T20 -> أكمل البيانات الأساسية / Complete core planning fields | R39: Reflection | S39: =M11 -> 0
A40: =TRACKER!A21 -> 20 | B40: =TRACKER!F21 | C40: =TRACKER!G21 | D40: =TRACKER!H21 | E40: =TRACKER!I21 | F40: =TRACKER!R21 -> 0 | G40: =TRACKER!S21 -> لم يبدأ / Not Started | H40: =TRACKER!T21 -> أكمل البيانات الأساسية / Complete core planning fields
...

Sheet TRACKER
A1: الأسبوع Week | B1: المعلم Teacher | C1: المرحلة Phase | D1: الصف Grade | E1: الشعبة Section | F1: التاريخ Date | G1: المحور Domain | H1: الوحدة Unit | I1: عنوان الدرس Lesson Title | J1: معيار النجاح Success Criterion | K1: نواتج التعلّم Learning Outcomes | L1: البيانات الأساسية Core Planning (17) | M1: التمايز Differentiation (4) | N1: الحصة الأولى First Period (9) | O1: الحصة الثانية Second Period (9) | P1: التأمل Reflection (1) | Q1: المنجز Completed | R1: نسبة الإنجاز Completion % | S1: الحالة Status | T1: المتابعة التالية Next Action
A2: 1 | B2: =IF('WEEK 1'!C2="","",'WEEK 1'!C2) | C2: =IF('WEEK 1'!I2="","",'WEEK 1'!I2) | D2: =IF('WEEK 1'!C3="","",'WEEK 1'!C3) | E2: =IF('WEEK 1'!I3="","",'WEEK 1'!I3) | F2: =IF('WEEK 1'!C5="","",'WEEK 1'!C5) | G2: =IF('WEEK 1'!C6="","",'WEEK 1'!C6) | H2: =IF('WEEK 1'!C8="","",'WEEK 1'!C8) | I2: =IF('WEEK 1'!A10="","",'WEEK 1'!A10) | J2: =IF('WEEK 1'!C7="","",'WEEK 1'!C7) -> أحكام الإسلام ومقاصده | يُحلّل الطالب خطوات العبادة أو الحكم الشرعي، ويُميّز الأداء الصحيح من غير الصحيح. / Islamic Rulings and Objectives | The student analyzes the steps of an act of worship or a legal ruling and distinguishes correct from incorrect practice. | K2: =IF('WEEK 1'!I7="","",'WEEK 1'!I7) | L2: =--('WEEK 1'!C2<>"")+--('WEEK 1'!I2<>"")+--('WEEK 1'!C3<>"")+--('WEEK 1'!I3<>"")+--('WEEK 1'!C4<>"")+--('WEEK 1'!I4<>"")+--('WEEK 1'!C5<>"")+--('WEEK 1'!C6<>"")+--('WEEK 1'!C7<>"")+--('WEEK 1'!I7<>"")+--('WEEK 1'!C8<>"")+--('WEEK 1'!A10<>"")+--('WEEK 1'!D10<>"")+--('WEEK 1'!H10<>"")+--(COUNTA('WEEK 1'!A12:D12)>0)+--('WEEK 1'!E12<>"")+--('WEEK 1'!H12<>"") -> 1 | M2: =--(LEN('WEEK 1'!B14)>LEN(LISTS!$Q$2))+--(LEN('WEEK 1'!D14)>LEN(LISTS!$Q$2))+--(LEN('WEEK 1'!F14)>LEN(LISTS!$Q$2))+--(LEN('WEEK 1'!H14)>LEN(LISTS!$Q$2)) -> 0 | N2: =--('WEEK 1'!B17<>"")+--('WEEK 1'!B18<>"")+--('WEEK 1'!B19<>"")+--('WEEK 1'!B20<>"")+--('WEEK 1'!B21<>"")+--(LEN('WEEK 1'!B22)>LEN(LISTS!$P$2))+--('WEEK 1'!B23<>"")+--('WEEK 1'!B24<>"")+--('WEEK 1'!B25<>"") -> 0 | O2: =--('WEEK 1'!G17<>"")+--('WEEK 1'!G18<>"")+--('WEEK 1'!G19<>"")+--('WEEK 1'!G20<>"")+--('WEEK 1'!G21<>"")+--(LEN('WEEK 1'!G22)>LEN(LISTS!$P$2))+--('WEEK 1'!G23<>"")+--('WEEK 1'!G24<>"")+--('WEEK 1'!G25<>"") -> 0 | P2: =--(LEN('WEEK 1'!B26)>LEN(LISTS!$R$2)) -> 0 | Q2: =SUM(L2:P2) -> 1 | R2: =Q2/40 -> 0.025 | S2: =IF(R2=0,"لم يبدأ / Not Started",IF(R2>=1,"مكتمل / Complete","قيد التنفيذ / In Progress")) -> قيد التنفيذ / In Progress | T2: =IF(R2>=1,"مكتمل / Complete",IF(L2<17,"أكمل البيانات الأساسية / Complete core planning fields",IF(M2<4,"أكمل التمايز / Complete differentiation",IF(N2<9,"أكمل الحصة الأولى / Complete First Period",IF(O2<9,"أكمل الحصة الثانية / Complete Second Period","أكمل تأمل المعلم / Complete teacher reflection"))))) -> أكمل البيانات الأساسية / Complete core planning fields
A3: 2 | B3: =IF('WEEK 2'!C2="","",'WEEK 2'!C2) | C3: =IF('WEEK 2'!I2="","",'WEEK 2'!I2) | D3: =IF('WEEK 2'!C3="","",'WEEK 2'!C3) | E3: =IF('WEEK 2'!I3="","",'WEEK 2'!I3) | F3: =IF('WEEK 2'!C5="","",'WEEK 2'!C5) | G3: =IF('WEEK 2'!C6="","",'WEEK 2'!C6) | H3: =IF('WEEK 2'!C8="","",'WEEK 2'!C8) | I3: =IF('WEEK 2'!A10="","",'WEEK 2'!A10) | J3: =IF('WEEK 2'!C7="","",'WEEK 2'!C7) | K3: =IF('WEEK 2'!I7="","",'WEEK 2'!I7) | L3: =--('WEEK 2'!C2<>"")+--('WEEK 2'!I2<>"")+--('WEEK 2'!C3<>"")+--('WEEK 2'!I3<>"")+--('WEEK 2'!C4<>"")+--('WEEK 2'!I4<>"")+--('WEEK 2'!C5<>"")+--('WEEK 2'!C6<>"")+--('WEEK 2'!C7<>"")+--('WEEK 2'!I7<>"")+--('WEEK 2'!C8<>"")+--('WEEK 2'!A10<>"")+--('WEEK 2'!D10<>"")+--('WEEK 2'!H10<>"")+--(COUNTA('WEEK 2'!A12:D12)>0)+--('WEEK 2'!E12<>"")+--('WEEK 2'!H12<>"") -> 0 | M3: =--(LEN('WEEK 2'!B14)>LEN(LISTS!$Q$2))+--(LEN('WEEK 2'!D14)>LEN(LISTS!$Q$2))+--(LEN('WEEK 2'!F14)>LEN(LISTS!$Q$2))+--(LEN('WEEK 2'!H14)>LEN(LISTS!$Q$2)) -> 0 | N3: =--('WEEK 2'!B17<>"")+--('WEEK 2'!B18<>"")+--('WEEK 2'!B19<>"")+--('WEEK 2'!B20<>"")+--('WEEK 2'!B21<>"")+--(LEN('WEEK 2'!B22)>LEN(LISTS!$P$2))+--('WEEK 2'!B23<>"")+--('WEEK 2'!B24<>"")+--('WEEK 2'!B25<>"") -> 0 | O3: =--('WEEK 2'!G17<>"")+--('WEEK 2'!G18<>"")+--('WEEK 2'!G19<>"")+--('WEEK 2'!G20<>"")+--('WEEK 2'!G21<>"")+--(LEN('WEEK 2'!G22)>LEN(LISTS!$P$2))+--('WEEK 2'!G23<>"")+--('WEEK 2'!G24<>"")+--('WEEK 2'!G25<>"") -> 0 | P3: =--(LEN('WEEK 2'!B26)>LEN(LISTS!$R$2)) -> 0 | Q3: =SUM(L3:P3) -> 0 | R3: =Q3/40 -> 0 | S3: =IF(R3=0,"لم يبدأ / Not Started",IF(R3>=1,"مكتمل / Complete","قيد التنفيذ / In Progress")) -> لم يبدأ / Not Started | T3: =IF(R3>=1,"مكتمل / Complete",IF(L3<17,"أكمل البيانات الأساسية / Complete core planning fields",IF(M3<4,"أكمل التمايز / Complete differentiation",IF(N3<9,"أكمل الحصة الأولى / Complete First Period",IF(O3<9,"أكمل الحصة الثانية / Complete Second Period","أكمل تأمل المعلم / Complete teacher reflection"))))) -> أكمل البيانات الأساسية / Complete core planning fields
A4: 3 | B4: =IF('WEEK 3'!C2="","",'WEEK 3'!C2) | C4: =IF('WEEK 3'!I2="","",'WEEK 3'!I2) | D4: =IF('WEEK 3'!C3="","",'WEEK 3'!C3) | E4: =IF('WEEK 3'!I3="","",'WEEK 3'!I3) | F4: =IF('WEEK 3'!C5="","",'WEEK 3'!C5) | G4: =IF('WEEK 3'!C6="","",'WEEK 3'!C6) | H4: =IF('WEEK 3'!C8="","",'WEEK 3'!C8) | I4: =IF('WEEK 3'!A10="","",'WEEK 3'!A10) | J4: =IF('WEEK 3'!C7="","",'WEEK 3'!C7) | K4: =IF('WEEK 3'!I7="","",'WEEK 3'!I7) | L4: =--('WEEK 3'!C2<>"")+--('WEEK 3'!I2<>"")+--('WEEK 3'!C3<>"")+--('WEEK 3'!I3<>"")+--('WEEK 3'!C4<>"")+--('WEEK 3'!I4<>"")+--('WEEK 3'!C5<>"")+--('WEEK 3'!C6<>"")+--('WEEK 3'!C7<>"")+--('WEEK 3'!I7<>"")+--('WEEK 3'!C8<>"")+--('WEEK 3'!A10<>"")+--('WEEK 3'!D10<>"")+--('WEEK 3'!H10<>"")+--(COUNTA('WEEK 3'!A12:D12)>0)+--('WEEK 3'!E12<>"")+--('WEEK 3'!H12<>"") -> 0 | M4: =--(LEN('WEEK 3'!B14)>LEN(LISTS!$Q$2))+--(LEN('WEEK 3'!D14)>LEN(LISTS!$Q$2))+--(LEN('WEEK 3'!F14)>LEN(LISTS!$Q$2))+--(LEN('WEEK 3'!H14)>LEN(LISTS!$Q$2)) -> 0 | N4: =--('WEEK 3'!B17<>"")+--('WEEK 3'!B18<>"")+--('WEEK 3'!B19<>"")+--('WEEK 3'!B20<>"")+--('WEEK 3'!B21<>"")+--(LEN('WEEK 3'!B22)>LEN(LISTS!$P$2))+--('WEEK 3'!B23<>"")+--('WEEK 3'!B24<>"")+--('WEEK 3'!B25<>"") -> 0 | O4: =--('WEEK 3'!G17<>"")+--('WEEK 3'!G18<>"")+--('WEEK 3'!G19<>"")+--('WEEK 3'!G20<>"")+--('WEEK 3'!G21<>"")+--(LEN('WEEK 3'!G22)>LEN(LISTS!$P$2))+--('WEEK 3'!G23<>"")+--('WEEK 3'!G24<>"")+--('WEEK 3'!G25<>"") -> 0 | P4: =--(LEN('WEEK 3'!B26)>LEN(LISTS!$R$2)) -> 0 | Q4: =SUM(L4:P4) -> 0 | R4: =Q4/40 -> 0 | S4: =IF(R4=0,"لم يبدأ / Not Started",IF(R4>=1,"مكتمل / Complete","قيد التنفيذ / In Progress")) -> لم يبدأ / Not Started | T4: =IF(R4>=1,"مكتمل / Complete",IF(L4<17,"أكمل البيانات الأساسية / Complete core planning fields",IF(M4<4,"أكمل التمايز / Complete differentiation",IF(N4<9,"أكمل الحصة الأولى / Complete First Period",IF(O4<9,"أكمل الحصة الثانية / Complete Second Period","أكمل تأمل المعلم / Complete teacher reflection"))))) -> أكمل البيانات الأساسية / Complete core planning fields
A5: 4 | B5: =IF('WEEK 4'!C2="","",'WEEK 4'!C2) | C5: =IF('WEEK 4'!I2="","",'WEEK 4'!I2) | D5: =IF('WEEK 4'!C3="","",'WEEK 4'!C3) | E5: =IF('WEEK 4'!I3="","",'WEEK 4'!I3) | F5: =IF('WEEK 4'!C5="","",'WEEK 4'!C5) | G5: =IF('WEEK 4'!C6="","",'WEEK 4'!C6) | H5: =IF('WEEK 4'!C8="","",'WEEK 4'!C8) | I5: =IF('WEEK 4'!A10="","",'WEEK 4'!A10) | J5: =IF('WEEK 4'!C7="","",'WEEK 4'!C7) | K5: =IF('WEEK 4'!I7="","",'WEEK 4'!I7) | L5: =--('WEEK 4'!C2<>"")+--('WEEK 4'!I2<>"")+--('WEEK 4'!C3<>"")+--('WEEK 4'!I3<>"")+--('WEEK 4'!C4<>"")+--('WEEK 4'!I4<>"")+--('WEEK 4'!C5<>"")+--('WEEK 4'!C6<>"")+--('WEEK 4'!C7<>"")+--('WEEK 4'!I7<>"")+--('WEEK 4'!C8<>"")+--('WEEK 4'!A10<>"")+--('WEEK 4'!D10<>"")+--('WEEK 4'!H10<>"")+--(COUNTA('WEEK 4'!A12:D12)>0)+--('WEEK 4'!E12<>"")+--('WEEK 4'!H12<>"") -> 0 | M5: =--(LEN('WEEK 4'!B14)>LEN(LISTS!$Q$2))+--(LEN('WEEK 4'!D14)>LEN(LISTS!$Q$2))+--(LEN('WEEK 4'!F14)>LEN(LISTS!$Q$2))+--(LEN('WEEK 4'!H14)>LEN(LISTS!$Q$2)) -> 0 | N5: =--('WEEK 4'!B17<>"")+--('WEEK 4'!B18<>"")+--('WEEK 4'!B19<>"")+--('WEEK 4'!B20<>"")+--('WEEK 4'!B21<>"")+--(LEN('WEEK 4'!B22)>LEN(LISTS!$P$2))+--('WEEK 4'!B23<>"")+--('WEEK 4'!B24<>"")+--('WEEK 4'!B25<>"") -> 0 | O5: =--('WEEK 4'!G17<>"")+--('WEEK 4'!G18<>"")+--('WEEK 4'!G19<>"")+--('WEEK 4'!G20<>"")+--('WEEK 4'!G21<>"")+--(LEN('WEEK 4'!G22)>LEN(LISTS!$P$2))+--('WEEK 4'!G23<>"")+--('WEEK 4'!G24<>"")+--('WEEK 4'!G25<>"") -> 0 | P5: =--(LEN('WEEK 4'!B26)>LEN(LISTS!$R$2)) -> 0 | Q5: =SUM(L5:P5) -> 0 | R5: =Q5/40 -> 0 | S5: =IF(R5=0,"لم يبدأ / Not Started",IF(R5>=1,"مكتمل / Complete","قيد التنفيذ / In Progress")) -> لم يبدأ / Not Started | T5: =IF(R5>=1,"مكتمل / Complete",IF(L5<17,"أكمل البيانات الأساسية / Complete core planning fields",IF(M5<4,"أكمل التمايز / Complete differentiation",IF(N5<9,"أكمل الحصة الأولى / Complete First Period",IF(O5<9,"أكمل الحصة الثانية / Complete Second Period","أكمل تأمل المعلم / Complete teacher reflection"))))) -> أكمل البيانات الأساسية / Complete core planning fields
A6: 5 | B6: =IF('WEEK 5'!C2="","",'WEEK 5'!C2) | C6: =IF('WEEK 5'!I2="","",'WEEK 5'!I2) | D6: =IF('WEEK 5'!C3="","",'WEEK 5'!C3) | E6: =IF('WEEK 5'!I3="","",'WEEK 5'!I3) | F6: =IF('WEEK 5'!C5="","",'WEEK 5'!C5) | G6: =IF('WEEK 5'!C6="","",'WEEK 5'!C6) | H6: =IF('WEEK 5'!C8="","",'WEEK 5'!C8) | I6: =IF('WEEK 5'!A10="","",'WEEK 5'!A10) | J6: =IF('WEEK 5'!C7="","",'WEEK 5'!C7) | K6: =IF('WEEK 5'!I7="","",'WEEK 5'!I7) | L6: =--('WEEK 5'!C2<>"")+--('WEEK 5'!I2<>"")+--('WEEK 5'!C3<>"")+--('WEEK 5'!I3<>"")+--('WEEK 5'!C4<>"")+--('WEEK 5'!I4<>"")+--('WEEK 5'!C5<>"")+--('WEEK 5'!C6<>"")+--('WEEK 5'!C7<>"")+--('WEEK 5'!I7<>"")+--('WEEK 5'!C8<>"")+--('WEEK 5'!A10<>"")+--('WEEK 5'!D10<>"")+--('WEEK 5'!H10<>"")+--(COUNTA('WEEK 5'!A12:D12)>0)+--('WEEK 5'!E12<>"")+--('WEEK 5'!H12<>"") -> 0 | M6: =--(LEN('WEEK 5'!B14)>LEN(LISTS!$Q$2))+--(LEN('WEEK 5'!D14)>LEN(LISTS!$Q$2))+--(LEN('WEEK 5'!F14)>LEN(LISTS!$Q$2))+--(LEN('WEEK 5'!H14)>LEN(LISTS!$Q$2)) -> 0 | N6: =--('WEEK 5'!B17<>"")+--('WEEK 5'!B18<>"")+--('WEEK 5'!B19<>"")+--('WEEK 5'!B20<>"")+--('WEEK 5'!B21<>"")+--(LEN('WEEK 5'!B22)>LEN(LISTS!$P$2))+--('WEEK 5'!B23<>"")+--('WEEK 5'!B24<>"")+--('WEEK 5'!B25<>"") -> 0 | O6: =--('WEEK 5'!G17<>"")+--('WEEK 5'!G18<>"")+--('WEEK 5'!G19<>"")+--('WEEK 5'!G20<>"")+--('WEEK 5'!G21<>"")+--(LEN('WEEK 5'!G22)>LEN(LISTS!$P$2))+--('WEEK 5'!G23<>"")+--('WEEK 5'!G24<>"")+--('WEEK 5'!G25<>"") -> 0 | P6: =--(LEN('WEEK 5'!B26)>LEN(LISTS!$R$2)) -> 0 | Q6: =SUM(L6:P6) -> 0 | R6: =Q6/40 -> 0 | S6: =IF(R6=0,"لم يبدأ / Not Started",IF(R6>=1,"مكتمل / Complete","قيد التنفيذ / In Progress")) -> لم يبدأ / Not Started | T6: =IF(R6>=1,"مكتمل / Complete",IF(L6<17,"أكمل البيانات الأساسية / Complete core planning fields",IF(M6<4,"أكمل التمايز / Complete differentiation",IF(N6<9,"أكمل الحصة الأولى / Complete First Period",IF(O6<9,"أكمل الحصة الثانية / Complete Second Period","أكمل تأمل المعلم / Complete teacher reflection"))))) -> أكمل البيانات الأساسية / Complete core planning fields
A7: 6 | B7: =IF('WEEK 6'!C2="","",'WEEK 6'!C2) | C7: =IF('WEEK 6'!I2="","",'WEEK 6'!I2) | D7: =IF('WEEK 6'!C3="","",'WEEK 6'!C3) | E7: =IF('WEEK 6'!I3="","",'WEEK 6'!I3) | F7: =IF('WEEK 6'!C5="","",'WEEK 6'!C5) | G7: =IF('WEEK 6'!C6="","",'WEEK 6'!C6) | H7: =IF('WEEK 6'!C8="","",'WEEK 6'!C8) | I7: =IF('WEEK 6'!A10="","",'WEEK 6'!A10) | J7: =IF('WEEK 6'!C7="","",'WEEK 6'!C7) | K7: =IF('WEEK 6'!I7="","",'WEEK 6'!I7) | L7: =--('WEEK 6'!C2<>"")+--('WEEK 6'!I2<>"")+--('WEEK 6'!C3<>"")+--('WEEK 6'!I3<>"")+--('WEEK 6'!C4<>"")+--('WEEK 6'!I4<>"")+--('WEEK 6'!C5<>"")+--('WEEK 6'!C6<>"")+--('WEEK 6'!C7<>"")+--('WEEK 6'!I7<>"")+--('WEEK 6'!C8<>"")+--('WEEK 6'!A10<>"")+--('WEEK 6'!D10<>"")+--('WEEK 6'!H10<>"")+--(COUNTA('WEEK 6'!A12:D12)>0)+--('WEEK 6'!E12<>"")+--('WEEK 6'!H12<>"") -> 0 | M7: =--(LEN('WEEK 6'!B14)>LEN(LISTS!$Q$2))+--(LEN('WEEK 6'!D14)>LEN(LISTS!$Q$2))+--(LEN('WEEK 6'!F14)>LEN(LISTS!$Q$2))+--(LEN('WEEK 6'!H14)>LEN(LISTS!$Q$2)) -> 0 | N7: =--('WEEK 6'!B17<>"")+--('WEEK 6'!B18<>"")+--('WEEK 6'!B19<>"")+--('WEEK 6'!B20<>"")+--('WEEK 6'!B21<>"")+--(LEN('WEEK 6'!B22)>LEN(LISTS!$P$2))+--('WEEK 6'!B23<>"")+--('WEEK 6'!B24<>"")+--('WEEK 6'!B25<>"") -> 0 | O7: =--('WEEK 6'!G17<>"")+--('WEEK 6'!G18<>"")+--('WEEK 6'!G19<>"")+--('WEEK 6'!G20<>"")+--('WEEK 6'!G21<>"")+--(LEN('WEEK 6'!G22)>LEN(LISTS!$P$2))+--('WEEK 6'!G23<>"")+--('WEEK 6'!G24<>"")+--('WEEK 6'!G25<>"") -> 0 | P7: =--(LEN('WEEK 6'!B26)>LEN(LISTS!$R$2)) -> 0 | Q7: =SUM(L7:P7) -> 0 | R7: =Q7/40 -> 0 | S7: =IF(R7=0,"لم يبدأ / Not Started",IF(R7>=1,"مكتمل / Complete","قيد التنفيذ / In Progress")) -> لم يبدأ / Not Started | T7: =IF(R7>=1,"مكتمل / Complete",IF(L7<17,"أكمل البيانات الأساسية / Complete core planning fields",IF(M7<4,"أكمل التمايز / Complete differentiation",IF(N7<9,"أكمل الحصة الأولى / Complete First Period",IF(O7<9,"أكمل الحصة الثانية / Complete Second Period","أكمل تأمل المعلم / Complete teacher reflection"))))) -> أكمل البيانات الأساسية / Complete core planning fields
A8: 7 | B8: =IF('WEEK 7'!C2="","",'WEEK 7'!C2) | C8: =IF('WEEK 7'!I2="","",'WEEK 7'!I2) | D8: =IF('WEEK 7'!C3="","",'WEEK 7'!C3) | E8: =IF('WEEK 7'!I3="","",'WEEK 7'!I3) | F8: =IF('WEEK 7'!C5="","",'WEEK 7'!C5) | G8: =IF('WEEK 7'!C6="","",'WEEK 7'!C6) | H8: =IF('WEEK 7'!C8="","",'WEEK 7'!C8) | I8: =IF('WEEK 7'!A10="","",'WEEK 7'!A10) | J8: =IF('WEEK 7'!C7="","",'WEEK 7'!C7) | K8: =IF('WEEK 7'!I7="","",'WEEK 7'!I7) | L8: =--('WEEK 7'!C2<>"")+--('WEEK 7'!I2<>"")+--('WEEK 7'!C3<>"")+--('WEEK 7'!I3<>"")+--('WEEK 7'!C4<>"")+--('WEEK 7'!I4<>"")+--('WEEK 7'!C5<>"")+--('WEEK 7'!C6<>"")+--('WEEK 7'!C7<>"")+--('WEEK 7'!I7<>"")+--('WEEK 7'!C8<>"")+--('WEEK 7'!A10<>"")+--('WEEK 7'!D10<>"")+--('WEEK 7'!H10<>"")+--(COUNTA('WEEK 7'!A12:D12)>0)+--('WEEK 7'!E12<>"")+--('WEEK 7'!H12<>"") -> 0 | M8: =--(LEN('WEEK 7'!B14)>LEN(LISTS!$Q$2))+--(LEN('WEEK 7'!D14)>LEN(LISTS!$Q$2))+--(LEN('WEEK 7'!F14)>LEN(LISTS!$Q$2))+--(LEN('WEEK 7'!H14)>LEN(LISTS!$Q$2)) -> 0 | N8: =--('WEEK 7'!B17<>"")+--('WEEK 7'!B18<>"")+--('WEEK 7'!B19<>"")+--('WEEK 7'!B20<>"")+--('WEEK 7'!B21<>"")+--(LEN('WEEK 7'!B22)>LEN(LISTS!$P$2))+--('WEEK 7'!B23<>"")+--('WEEK 7'!B24<>"")+--('WEEK 7'!B25<>"") -> 0 | O8: =--('WEEK 7'!G17<>"")+--('WEEK 7'!G18<>"")+--('WEEK 7'!G19<>"")+--('WEEK 7'!G20<>"")+--('WEEK 7'!G21<>"")+--(LEN('WEEK 7'!G22)>LEN(LISTS!$P$2))+--('WEEK 7'!G23<>"")+--('WEEK 7'!G24<>"")+--('WEEK 7'!G25<>"") -> 0 | P8: =--(LEN('WEEK 7'!B26)>LEN(LISTS!$R$2)) -> 0 | Q8: =SUM(L8:P8) -> 0 | R8: =Q8/40 -> 0 | S8: =IF(R8=0,"لم يبدأ / Not Started",IF(R8>=1,"مكتمل / Complete","قيد التنفيذ / In Progress")) -> لم يبدأ / Not Started | T8: =IF(R8>=1,"مكتمل / Complete",IF(L8<17,"أكمل البيانات الأساسية / Complete core planning fields",IF(M8<4,"أكمل التمايز / Complete differentiation",IF(N8<9,"أكمل الحصة الأولى / Complete First Period",IF(O8<9,"أكمل الحصة الثانية / Complete Second Period","أكمل تأمل المعلم / Complete teacher reflection"))))) -> أكمل البيانات الأساسية / Complete core planning fields
A9: 8 | B9: =IF('WEEK 8'!C2="","",'WEEK 8'!C2) | C9: =IF('WEEK 8'!I2="","",'WEEK 8'!I2) | D9: =IF('WEEK 8'!C3="","",'WEEK 8'!C3) | E9: =IF('WEEK 8'!I3="","",'WEEK 8'!I3) | F9: =IF('WEEK 8'!C5="","",'WEEK 8'!C5) | G9: =IF('WEEK 8'!C6="","",'WEEK 8'!C6) | H9: =IF('WEEK 8'!C8="","",'WEEK 8'!C8) | I9: =IF('WEEK 8'!A10="","",'WEEK 8'!A10) | J9: =IF('WEEK 8'!C7="","",'WEEK 8'!C7) | K9: =IF('WEEK 8'!I7="","",'WEEK 8'!I7) | L9: =--('WEEK 8'!C2<>"")+--('WEEK 8'!I2<>"")+--('WEEK 8'!C3<>"")+--('WEEK 8'!I3<>"")+--('WEEK 8'!C4<>"")+--('WEEK 8'!I4<>"")+--('WEEK 8'!C5<>"")+--('WEEK 8'!C6<>"")+--('WEEK 8'!C7<>"")+--('WEEK 8'!I7<>"")+--('WEEK 8'!C8<>"")+--('WEEK 8'!A10<>"")+--('WEEK 8'!D10<>"")+--('WEEK 8'!H10<>"")+--(COUNTA('WEEK 8'!A12:D12)>0)+--('WEEK 8'!E12<>"")+--('WEEK 8'!H12<>"") -> 0 | M9: =--(LEN('WEEK 8'!B14)>LEN(LISTS!$Q$2))+--(LEN('WEEK 8'!D14)>LEN(LISTS!$Q$2))+--(LEN('WEEK 8'!F14)>LEN(LISTS!$Q$2))+--(LEN('WEEK 8'!H14)>LEN(LISTS!$Q$2)) -> 0 | N9: =--('WEEK 8'!B17<>"")+--('WEEK 8'!B18<>"")+--('WEEK 8'!B19<>"")+--('WEEK 8'!B20<>"")+--('WEEK 8'!B21<>"")+--(LEN('WEEK 8'!B22)>LEN(LISTS!$P$2))+--('WEEK 8'!B23<>"")+--('WEEK 8'!B24<>"")+--('WEEK 8'!B25<>"") -> 0 | O9: =--('WEEK 8'!G17<>"")+--('WEEK 8'!G18<>"")+--('WEEK 8'!G19<>"")+--('WEEK 8'!G20<>"")+--('WEEK 8'!G21<>"")+--(LEN('WEEK 8'!G22)>LEN(LISTS!$P$2))+--('WEEK 8'!G23<>"")+--('WEEK 8'!G24<>"")+--('WEEK 8'!G25<>"") -> 0 | P9: =--(LEN('WEEK 8'!B26)>LEN(LISTS!$R$2)) -> 0 | Q9: =SUM(L9:P9) -> 0 | R9: =Q9/40 -> 0 | S9: =IF(R9=0,"لم يبدأ / Not Started",IF(R9>=1,"مكتمل / Complete","قيد التنفيذ / In Progress")) -> لم يبدأ / Not Started | T9: =IF(R9>=1,"مكتمل / Complete",IF(L9<17,"أكمل البيانات الأساسية / Complete core planning fields",IF(M9<4,"أكمل التمايز / Complete differentiation",IF(N9<9,"أكمل الحصة الأولى / Complete First Period",IF(O9<9,"أكمل الحصة الثانية / Complete Second Period","أكمل تأمل المعلم / Complete teacher reflection"))))) -> أكمل البيانات الأساسية / Complete core planning fields
A10: 9 | B10: =IF('WEEK 9'!C2="","",'WEEK 9'!C2) | C10: =IF('WEEK 9'!I2="","",'WEEK 9'!I2) | D10: =IF('WEEK 9'!C3="","",'WEEK 9'!C3) | E10: =IF('WEEK 9'!I3="","",'WEEK 9'!I3) | F10: =IF('WEEK 9'!C5="","",'WEEK 9'!C5) | G10: =IF('WEEK 9'!C6="","",'WEEK 9'!C6) | H10: =IF('WEEK 9'!C8="","",'WEEK 9'!C8) | I10: =IF('WEEK 9'!A10="","",'WEEK 9'!A10) | J10: =IF('WEEK 9'!C7="","",'WEEK 9'!C7) | K10: =IF('WEEK 9'!I7="","",'WEEK 9'!I7) | L10: =--('WEEK 9'!C2<>"")+--('WEEK 9'!I2<>"")+--('WEEK 9'!C3<>"")+--('WEEK 9'!I3<>"")+--('WEEK 9'!C4<>"")+--('WEEK 9'!I4<>"")+--('WEEK 9'!C5<>"")+--('WEEK 9'!C6<>"")+--('WEEK 9'!C7<>"")+--('WEEK 9'!I7<>"")+--('WEEK 9'!C8<>"")+--('WEEK 9'!A10<>"")+--('WEEK 9'!D10<>"")+--('WEEK 9'!H10<>"")+--(COUNTA('WEEK 9'!A12:D12)>0)+--('WEEK 9'!E12<>"")+--('WEEK 9'!H12<>"") -> 0 | M10: =--(LEN('WEEK 9'!B14)>LEN(LISTS!$Q$2))+--(LEN('WEEK 9'!D14)>LEN(LISTS!$Q$2))+--(LEN('WEEK 9'!F14)>LEN(LISTS!$Q$2))+--(LEN('WEEK 9'!H14)>LEN(LISTS!$Q$2)) -> 0 | N10: =--('WEEK 9'!B17<>"")+--('WEEK 9'!B18<>"")+--('WEEK 9'!B19<>"")+--('WEEK 9'!B20<>"")+--('WEEK 9'!B21<>"")+--(LEN('WEEK 9'!B22)>LEN(LISTS!$P$2))+--('WEEK 9'!B23<>"")+--('WEEK 9'!B24<>"")+--('WEEK 9'!B25<>"") -> 0 | O10: =--('WEEK 9'!G17<>"")+--('WEEK 9'!G18<>"")+--('WEEK 9'!G19<>"")+--('WEEK 9'!G20<>"")+--('WEEK 9'!G21<>"")+--(LEN('WEEK 9'!G22)>LEN(LISTS!$P$2))+--('WEEK 9'!G23<>"")+--('WEEK 9'!G24<>"")+--('WEEK 9'!G25<>"") -> 0 | P10: =--(LEN('WEEK 9'!B26)>LEN(LISTS!$R$2)) -> 0 | Q10: =SUM(L10:P10) -> 0 | R10: =Q10/40 -> 0 | S10: =IF(R10=0,"لم يبدأ / Not Started",IF(R10>=1,"مكتمل / Complete","قيد التنفيذ / In Progress")) -> لم يبدأ / Not Started | T10: =IF(R10>=1,"مكتمل / Complete",IF(L10<17,"أكمل البيانات الأساسية / Complete core planning fields",IF(M10<4,"أكمل التمايز / Complete differentiation",IF(N10<9,"أكمل الحصة الأولى / Complete First Period",IF(O10<9,"أكمل الحصة الثانية / Complete Second Period","أكمل تأمل المعلم / Complete teacher reflection"))))) -> أكمل البيانات الأساسية / Complete core planning fields
A11: 10 | B11: =IF('WEEK 10'!C2="","",'WEEK 10'!C2) | C11: =IF('WEEK 10'!I2="","",'WEEK 10'!I2) | D11: =IF('WEEK 10'!C3="","",'WEEK 10'!C3) | E11: =IF('WEEK 10'!I3="","",'WEEK 10'!I3) | F11: =IF('WEEK 10'!C5="","",'WEEK 10'!C5) | G11: =IF('WEEK 10'!C6="","",'WEEK 10'!C6) | H11: =IF('WEEK 10'!C8="","",'WEEK 10'!C8) | I11: =IF('WEEK 10'!A10="","",'WEEK 10'!A10) | J11: =IF('WEEK 10'!C7="","",'WEEK 10'!C7) | K11: =IF('WEEK 10'!I7="","",'WEEK 10'!I7) | L11: =--('WEEK 10'!C2<>"")+--('WEEK 10'!I2<>"")+--('WEEK 10'!C3<>"")+--('WEEK 10'!I3<>"")+--('WEEK 10'!C4<>"")+--('WEEK 10'!I4<>"")+--('WEEK 10'!C5<>"")+--('WEEK 10'!C6<>"")+--('WEEK 10'!C7<>"")+--('WEEK 10'!I7<>"")+--('WEEK 10'!C8<>"")+--('WEEK 10'!A10<>"")+--('WEEK 10'!D10<>"")+--('WEEK 10'!H10<>"")+--(COUNTA('WEEK 10'!A12:D12)>0)+--('WEEK 10'!E12<>"")+--('WEEK 10'!H12<>"") -> 0 | M11: =--(LEN('WEEK 10'!B14)>LEN(LISTS!$Q$2))+--(LEN('WEEK 10'!D14)>LEN(LISTS!$Q$2))+--(LEN('WEEK 10'!F14)>LEN(LISTS!$Q$2))+--(LEN('WEEK 10'!H14)>LEN(LISTS!$Q$2)) -> 0 | N11: =--('WEEK 10'!B17<>"")+--('WEEK 10'!B18<>"")+--('WEEK 10'!B19<>"")+--('WEEK 10'!B20<>"")+--('WEEK 10'!B21<>"")+--(LEN('WEEK 10'!B22)>LEN(LISTS!$P$2))+--('WEEK 10'!B23<>"")+--('WEEK 10'!B24<>"")+--('WEEK 10'!B25<>"") -> 0 | O11: =--('WEEK 10'!G17<>"")+--('WEEK 10'!G18<>"")+--('WEEK 10'!G19<>"")+--('WEEK 10'!G20<>"")+--('WEEK 10'!G21<>"")+--(LEN('WEEK 10'!G22)>LEN(LISTS!$P$2))+--('WEEK 10'!G23<>"")+--('WEEK 10'!G24<>"")+--('WEEK 10'!G25<>"") -> 0 | P11: =--(LEN('WEEK 10'!B26)>LEN(LISTS!$R$2)) -> 0 | Q11: =SUM(L11:P11) -> 0 | R11: =Q11/40 -> 0 | S11: =IF(R11=0,"لم يبدأ / Not Started",IF(R11>=1,"مكتمل / Complete","قيد التنفيذ / In Progress")) -> لم يبدأ / Not Started | T11: =IF(R11>=1,"مكتمل / Complete",IF(L11<17,"أكمل البيانات الأساسية / Complete core planning fields",IF(M11<4,"أكمل التمايز / Complete differentiation",IF(N11<9,"أكمل الحصة الأولى / Complete First Period",IF(O11<9,"أكمل الحصة الثانية / Complete Second Period","أكمل تأمل المعلم / Complete teacher reflection"))))) -> أكمل البيانات الأساسية / Complete core planning fields
A12: 11 | B12: =IF('WEEK 11'!C2="","",'WEEK 11'!C2) | C12: =IF('WEEK 11'!I2="","",'WEEK 11'!I2) | D12: =IF('WEEK 11'!C3="","",'WEEK 11'!C3) | E12: =IF('WEEK 11'!I3="","",'WEEK 11'!I3) | F12: =IF('WEEK 11'!C5="","",'WEEK 11'!C5) | G12: =IF('WEEK 11'!C6="","",'WEEK 11'!C6) | H12: =IF('WEEK 11'!C8="","",'WEEK 11'!C8) | I12: =IF('WEEK 11'!A10="","",'WEEK 11'!A10) | J12: =IF('WEEK 11'!C7="","",'WEEK 11'!C7) | K12: =IF('WEEK 11'!I7="","",'WEEK 11'!I7) | L12: =--('WEEK 11'!C2<>"")+--('WEEK 11'!I2<>"")+--('WEEK 11'!C3<>"")+--('WEEK 11'!I3<>"")+--('WEEK 11'!C4<>"")+--('WEEK 11'!I4<>"")+--('WEEK 11'!C5<>"")+--('WEEK 11'!C6<>"")+--('WEEK 11'!C7<>"")+--('WEEK 11'!I7<>"")+--('WEEK 11'!C8<>"")+--('WEEK 11'!A10<>"")+--('WEEK 11'!D10<>"")+--('WEEK 11'!H10<>"")+--(COUNTA('WEEK 11'!A12:D12)>0)+--('WEEK 11'!E12<>"")+--('WEEK 11'!H12<>"") -> 0 | M12: =--(LEN('WEEK 11'!B14)>LEN(LISTS!$Q$2))+--(LEN('WEEK 11'!D14)>LEN(LISTS!$Q$2))+--(LEN('WEEK 11'!F14)>LEN(LISTS!$Q$2))+--(LEN('WEEK 11'!H14)>LEN(LISTS!$Q$2)) -> 0 | N12: =--('WEEK 11'!B17<>"")+--('WEEK 11'!B18<>"")+--('WEEK 11'!B19<>"")+--('WEEK 11'!B20<>"")+--('WEEK 11'!B21<>"")+--(LEN('WEEK 11'!B22)>LEN(LISTS!$P$2))+--('WEEK 11'!B23<>"")+--('WEEK 11'!B24<>"")+--('WEEK 11'!B25<>"") -> 0 | O12: =--('WEEK 11'!G17<>"")+--('WEEK 11'!G18<>"")+--('WEEK 11'!G19<>"")+--('WEEK 11'!G20<>"")+--('WEEK 11'!G21<>"")+--(LEN('WEEK 11'!G22)>LEN(LISTS!$P$2))+--('WEEK 11'!G23<>"")+--('WEEK 11'!G24<>"")+--('WEEK 11'!G25<>"") -> 0 | P12: =--(LEN('WEEK 11'!B26)>LEN(LISTS!$R$2)) -> 0 | Q12: =SUM(L12:P12) -> 0 | R12: =Q12/40 -> 0 | S12: =IF(R12=0,"لم يبدأ / Not Started",IF(R12>=1,"مكتمل / Complete","قيد التنفيذ / In Progress")) -> لم يبدأ / Not Started | T12: =IF(R12>=1,"مكتمل / Complete",IF(L12<17,"أكمل البيانات الأساسية / Complete core planning fields",IF(M12<4,"أكمل التمايز / Complete differentiation",IF(N12<9,"أكمل الحصة الأولى / Complete First Period",IF(O12<9,"أكمل الحصة الثانية / Complete Second Period","أكمل تأمل المعلم / Complete teacher reflection"))))) -> أكمل البيانات الأساسية / Complete core planning fields
A13: 12 | B13: =IF('WEEK 12'!C2="","",'WEEK 12'!C2) | C13: =IF('WEEK 12'!I2="","",'WEEK 12'!I2) | D13: =IF('WEEK 12'!C3="","",'WEEK 12'!C3) | E13: =IF('WEEK 12'!I3="","",'WEEK 12'!I3) | F13: =IF('WEEK 12'!C5="","",'WEEK 12'!C5) | G13: =IF('WEEK 12'!C6="","",'WEEK 12'!C6) | H13: =IF('WEEK 12'!C8="","",'WEEK 12'!C8) | I13: =IF('WEEK 12'!A10="","",'WEEK 12'!A10) | J13: =IF('WEEK 12'!C7="","",'WEEK 12'!C7) | K13: =IF('WEEK 12'!I7="","",'WEEK 12'!I7) | L13: =--('WEEK 12'!C2<>"")+--('WEEK 12'!I2<>"")+--('WEEK 12'!C3<>"")+--('WEEK 12'!I3<>"")+--('WEEK 12'!C4<>"")+--('WEEK 12'!I4<>"")+--('WEEK 12'!C5<>"")+--('WEEK 12'!C6<>"")+--('WEEK 12'!C7<>"")+--('WEEK 12'!I7<>"")+--('WEEK 12'!C8<>"")+--('WEEK 12'!A10<>"")+--('WEEK 12'!D10<>"")+--('WEEK 12'!H10<>"")+--(COUNTA('WEEK 12'!A12:D12)>0)+--('WEEK 12'!E12<>"")+--('WEEK 12'!H12<>"") -> 0 | M13: =--(LEN('WEEK 12'!B14)>LEN(LISTS!$Q$2))+--(LEN('WEEK 12'!D14)>LEN(LISTS!$Q$2))+--(LEN('WEEK 12'!F14)>LEN(LISTS!$Q$2))+--(LEN('WEEK 12'!H14)>LEN(LISTS!$Q$2)) -> 0 | N13: =--('WEEK 12'!B17<>"")+--('WEEK 12'!B18<>"")+--('WEEK 12'!B19<>"")+--('WEEK 12'!B20<>"")+--('WEEK 12'!B21<>"")+--(LEN('WEEK 12'!B22)>LEN(LISTS!$P$2))+--('WEEK 12'!B23<>"")+--('WEEK 12'!B24<>"")+--('WEEK 12'!B25<>"") -> 0 | O13: =--('WEEK 12'!G17<>"")+--('WEEK 12'!G18<>"")+--('WEEK 12'!G19<>"")+--('WEEK 12'!G20<>"")+--('WEEK 12'!G21<>"")+--(LEN('WEEK 12'!G22)>LEN(LISTS!$P$2))+--('WEEK 12'!G23<>"")+--('WEEK 12'!G24<>"")+--('WEEK 12'!G25<>"") -> 0 | P13: =--(LEN('WEEK 12'!B26)>LEN(LISTS!$R$2)) -> 0 | Q13: =SUM(L13:P13) -> 0 | R13: =Q13/40 -> 0 | S13: =IF(R13=0,"لم يبدأ / Not Started",IF(R13>=1,"مكتمل / Complete","قيد التنفيذ / In Progress")) -> لم يبدأ / Not Started | T13: =IF(R13>=1,"مكتمل / Complete",IF(L13<17,"أكمل البيانات الأساسية / Complete core planning fields",IF(M13<4,"أكمل التمايز / Complete differentiation",IF(N13<9,"أكمل الحصة الأولى / Complete First Period",IF(O13<9,"أكمل الحصة الثانية / Complete Second Period","أكمل تأمل المعلم / Complete teacher reflection"))))) -> أكمل البيانات الأساسية / Complete core planning fields
A14: 13 | B14: =IF('WEEK 13'!C2="","",'WEEK 13'!C2) | C14: =IF('WEEK 13'!I2="","",'WEEK 13'!I2) | D14: =IF('WEEK 13'!C3="","",'WEEK 13'!C3) | E14: =IF('WEEK 13'!I3="","",'WEEK 13'!I3) | F14: =IF('WEEK 13'!C5="","",'WEEK 13'!C5) | G14: =IF('WEEK 13'!C6="","",'WEEK 13'!C6) | H14: =IF('WEEK 13'!C8="","",'WEEK 13'!C8) | I14: =IF('WEEK 13'!A10="","",'WEEK 13'!A10) | J14: =IF('WEEK 13'!C7="","",'WEEK 13'!C7) | K14: =IF('WEEK 13'!I7="","",'WEEK 13'!I7) | L14: =--('WEEK 13'!C2<>"")+--('WEEK 13'!I2<>"")+--('WEEK 13'!C3<>"")+--('WEEK 13'!I3<>"")+--('WEEK 13'!C4<>"")+--('WEEK 13'!I4<>"")+--('WEEK 13'!C5<>"")+--('WEEK 13'!C6<>"")+--('WEEK 13'!C7<>"")+--('WEEK 13'!I7<>"")+--('WEEK 13'!C8<>"")+--('WEEK 13'!A10<>"")+--('WEEK 13'!D10<>"")+--('WEEK 13'!H10<>"")+--(COUNTA('WEEK 13'!A12:D12)>0)+--('WEEK 13'!E12<>"")+--('WEEK 13'!H12<>"") -> 0 | M14: =--(LEN('WEEK 13'!B14)>LEN(LISTS!$Q$2))+--(LEN('WEEK 13'!D14)>LEN(LISTS!$Q$2))+--(LEN('WEEK 13'!F14)>LEN(LISTS!$Q$2))+--(LEN('WEEK 13'!H14)>LEN(LISTS!$Q$2)) -> 0 | N14: =--('WEEK 13'!B17<>"")+--('WEEK 13'!B18<>"")+--('WEEK 13'!B19<>"")+--('WEEK 13'!B20<>"")+--('WEEK 13'!B21<>"")+--(LEN('WEEK 13'!B22)>LEN(LISTS!$P$2))+--('WEEK 13'!B23<>"")+--('WEEK 13'!B24<>"")+--('WEEK 13'!B25<>"") -> 0 | O14: =--('WEEK 13'!G17<>"")+--('WEEK 13'!G18<>"")+--('WEEK 13'!G19<>"")+--('WEEK 13'!G20<>"")+--('WEEK 13'!G21<>"")+--(LEN('WEEK 13'!G22)>LEN(LISTS!$P$2))+--('WEEK 13'!G23<>"")+--('WEEK 13'!G24<>"")+--('WEEK 13'!G25<>"") -> 0 | P14: =--(LEN('WEEK 13'!B26)>LEN(LISTS!$R$2)) -> 0 | Q14: =SUM(L14:P14) -> 0 | R14: =Q14/40 -> 0 | S14: =IF(R14=0,"لم يبدأ / Not Started",IF(R14>=1,"مكتمل / Complete","قيد التنفيذ / In Progress")) -> لم يبدأ / Not Started | T14: =IF(R14>=1,"مكتمل / Complete",IF(L14<17,"أكمل البيانات الأساسية / Complete core planning fields",IF(M14<4,"أكمل التمايز / Complete differentiation",IF(N14<9,"أكمل الحصة الأولى / Complete First Period",IF(O14<9,"أكمل الحصة الثانية / Complete Second Period","أكمل تأمل المعلم / Complete teacher reflection"))))) -> أكمل البيانات الأساسية / Complete core planning fields
A15: 14 | B15: =IF('WEEK 14'!C2="","",'WEEK 14'!C2) | C15: =IF('WEEK 14'!I2="","",'WEEK 14'!I2) | D15: =IF('WEEK 14'!C3="","",'WEEK 14'!C3) | E15: =IF('WEEK 14'!I3="","",'WEEK 14'!I3) | F15: =IF('WEEK 14'!C5="","",'WEEK 14'!C5) | G15: =IF('WEEK 14'!C6="","",'WEEK 14'!C6) | H15: =IF('WEEK 14'!C8="","",'WEEK 14'!C8) | I15: =IF('WEEK 14'!A10="","",'WEEK 14'!A10) | J15: =IF('WEEK 14'!C7="","",'WEEK 14'!C7) | K15: =IF('WEEK 14'!I7="","",'WEEK 14'!I7) | L15: =--('WEEK 14'!C2<>"")+--('WEEK 14'!I2<>"")+--('WEEK 14'!C3<>"")+--('WEEK 14'!I3<>"")+--('WEEK 14'!C4<>"")+--('WEEK 14'!I4<>"")+--('WEEK 14'!C5<>"")+--('WEEK 14'!C6<>"")+--('WEEK 14'!C7<>"")+--('WEEK 14'!I7<>"")+--('WEEK 14'!C8<>"")+--('WEEK 14'!A10<>"")+--('WEEK 14'!D10<>"")+--('WEEK 14'!H10<>"")+--(COUNTA('WEEK 14'!A12:D12)>0)+--('WEEK 14'!E12<>"")+--('WEEK 14'!H12<>"") -> 0 | M15: =--(LEN('WEEK 14'!B14)>LEN(LISTS!$Q$2))+--(LEN('WEEK 14'!D14)>LEN(LISTS!$Q$2))+--(LEN('WEEK 14'!F14)>LEN(LISTS!$Q$2))+--(LEN('WEEK 14'!H14)>LEN(LISTS!$Q$2)) -> 0 | N15: =--('WEEK 14'!B17<>"")+--('WEEK 14'!B18<>"")+--('WEEK 14'!B19<>"")+--('WEEK 14'!B20<>"")+--('WEEK 14'!B21<>"")+--(LEN('WEEK 14'!B22)>LEN(LISTS!$P$2))+--('WEEK 14'!B23<>"")+--('WEEK 14'!B24<>"")+--('WEEK 14'!B25<>"") -> 0 | O15: =--('WEEK 14'!G17<>"")+--('WEEK 14'!G18<>"")+--('WEEK 14'!G19<>"")+--('WEEK 14'!G20<>"")+--('WEEK 14'!G21<>"")+--(LEN('WEEK 14'!G22)>LEN(LISTS!$P$2))+--('WEEK 14'!G23<>"")+--('WEEK 14'!G24<>"")+--('WEEK 14'!G25<>"") -> 0 | P15: =--(LEN('WEEK 14'!B26)>LEN(LISTS!$R$2)) -> 0 | Q15: =SUM(L15:P15) -> 0 | R15: =Q15/40 -> 0 | S15: =IF(R15=0,"لم يبدأ / Not Started",IF(R15>=1,"مكتمل / Complete","قيد التنفيذ / In Progress")) -> لم يبدأ / Not Started | T15: =IF(R15>=1,"مكتمل / Complete",IF(L15<17,"أكمل البيانات الأساسية / Complete core planning fields",IF(M15<4,"أكمل التمايز / Complete differentiation",IF(N15<9,"أكمل الحصة الأولى / Complete First Period",IF(O15<9,"أكمل الحصة الثانية / Complete Second Period","أكمل تأمل المعلم / Complete teacher reflection"))))) -> أكمل البيانات الأساسية / Complete core planning fields
A16: 15 | B16: =IF('WEEK 15'!C2="","",'WEEK 15'!C2) | C16: =IF('WEEK 15'!I2="","",'WEEK 15'!I2) | D16: =IF('WEEK 15'!C3="","",'WEEK 15'!C3) | E16: =IF('WEEK 15'!I3="","",'WEEK 15'!I3) | F16: =IF('WEEK 15'!C5="","",'WEEK 15'!C5) | G16: =IF('WEEK 15'!C6="","",'WEEK 15'!C6) | H16: =IF('WEEK 15'!C8="","",'WEEK 15'!C8) | I16: =IF('WEEK 15'!A10="","",'WEEK 15'!A10) | J16: =IF('WEEK 15'!C7="","",'WEEK 15'!C7) | K16: =IF('WEEK 15'!I7="","",'WEEK 15'!I7) | L16: =--('WEEK 15'!C2<>"")+--('WEEK 15'!I2<>"")+--('WEEK 15'!C3<>"")+--('WEEK 15'!I3<>"")+--('WEEK 15'!C4<>"")+--('WEEK 15'!I4<>"")+--('WEEK 15'!C5<>"")+--('WEEK 15'!C6<>"")+--('WEEK 15'!C7<>"")+--('WEEK 15'!I7<>"")+--('WEEK 15'!C8<>"")+--('WEEK 15'!A10<>"")+--('WEEK 15'!D10<>"")+--('WEEK 15'!H10<>"")+--(COUNTA('WEEK 15'!A12:D12)>0)+--('WEEK 15'!E12<>"")+--('WEEK 15'!H12<>"") -> 0 | M16: =--(LEN('WEEK 15'!B14)>LEN(LISTS!$Q$2))+--(LEN('WEEK 15'!D14)>LEN(LISTS!$Q$2))+--(LEN('WEEK 15'!F14)>LEN(LISTS!$Q$2))+--(LEN('WEEK 15'!H14)>LEN(LISTS!$Q$2)) -> 0 | N16: =--('WEEK 15'!B17<>"")+--('WEEK 15'!B18<>"")+--('WEEK 15'!B19<>"")+--('WEEK 15'!B20<>"")+--('WEEK 15'!B21<>"")+--(LEN('WEEK 15'!B22)>LEN(LISTS!$P$2))+--('WEEK 15'!B23<>"")+--('WEEK 15'!B24<>"")+--('WEEK 15'!B25<>"") -> 0 | O16: =--('WEEK 15'!G17<>"")+--('WEEK 15'!G18<>"")+--('WEEK 15'!G19<>"")+--('WEEK 15'!G20<>"")+--('WEEK 15'!G21<>"")+--(LEN('WEEK 15'!G22)>LEN(LISTS!$P$2))+--('WEEK 15'!G23<>"")+--('WEEK 15'!G24<>"")+--('WEEK 15'!G25<>"") -> 0 | P16: =--(LEN('WEEK 15'!B26)>LEN(LISTS!$R$2)) -> 0 | Q16: =SUM(L16:P16) -> 0 | R16: =Q16/40 -> 0 | S16: =IF(R16=0,"لم يبدأ / Not Started",IF(R16>=1,"مكتمل / Complete","قيد التنفيذ / In Progress")) -> لم يبدأ / Not Started | T16: =IF(R16>=1,"مكتمل / Complete",IF(L16<17,"أكمل البيانات الأساسية / Complete core planning fields",IF(M16<4,"أكمل التمايز / Complete differentiation",IF(N16<9,"أكمل الحصة الأولى / Complete First Period",IF(O16<9,"أكمل الحصة الثانية / Complete Second Period","أكمل تأمل المعلم / Complete teacher reflection"))))) -> أكمل البيانات الأساسية / Complete core planning fields
A17: 16 | B17: =IF('WEEK 16'!C2="","",'WEEK 16'!C2) | C17: =IF('WEEK 16'!I2="","",'WEEK 16'!I2) | D17: =IF('WEEK 16'!C3="","",'WEEK 16'!C3) | E17: =IF('WEEK 16'!I3="","",'WEEK 16'!I3) | F17: =IF('WEEK 16'!C5="","",'WEEK 16'!C5) | G17: =IF('WEEK 16'!C6="","",'WEEK 16'!C6) | H17: =IF('WEEK 16'!C8="","",'WEEK 16'!C8) | I17: =IF('WEEK 16'!A10="","",'WEEK 16'!A10) | J17: =IF('WEEK 16'!C7="","",'WEEK 16'!C7) | K17: =IF('WEEK 16'!I7="","",'WEEK 16'!I7) | L17: =--('WEEK 16'!C2<>"")+--('WEEK 16'!I2<>"")+--('WEEK 16'!C3<>"")+--('WEEK 16'!I3<>"")+--('WEEK 16'!C4<>"")+--('WEEK 16'!I4<>"")+--('WEEK 16'!C5<>"")+--('WEEK 16'!C6<>"")+--('WEEK 16'!C7<>"")+--('WEEK 16'!I7<>"")+--('WEEK 16'!C8<>"")+--('WEEK 16'!A10<>"")+--('WEEK 16'!D10<>"")+--('WEEK 16'!H10<>"")+--(COUNTA('WEEK 16'!A12:D12)>0)+--('WEEK 16'!E12<>"")+--('WEEK 16'!H12<>"") -> 0 | M17: =--(LEN('WEEK 16'!B14)>LEN(LISTS!$Q$2))+--(LEN('WEEK 16'!D14)>LEN(LISTS!$Q$2))+--(LEN('WEEK 16'!F14)>LEN(LISTS!$Q$2))+--(LEN('WEEK 16'!H14)>LEN(LISTS!$Q$2)) -> 0 | N17: =--('WEEK 16'!B17<>"")+--('WEEK 16'!B18<>"")+--('WEEK 16'!B19<>"")+--('WEEK 16'!B20<>"")+--('WEEK 16'!B21<>"")+--(LEN('WEEK 16'!B22)>LEN(LISTS!$P$2))+--('WEEK 16'!B23<>"")+--('WEEK 16'!B24<>"")+--('WEEK 16'!B25<>"") -> 0 | O17: =--('WEEK 16'!G17<>"")+--('WEEK 16'!G18<>"")+--('WEEK 16'!G19<>"")+--('WEEK 16'!G20<>"")+--('WEEK 16'!G21<>"")+--(LEN('WEEK 16'!G22)>LEN(LISTS!$P$2))+--('WEEK 16'!G23<>"")+--('WEEK 16'!G24<>"")+--('WEEK 16'!G25<>"") -> 0 | P17: =--(LEN('WEEK 16'!B26)>LEN(LISTS!$R$2)) -> 0 | Q17: =SUM(L17:P17) -> 0 | R17: =Q17/40 -> 0 | S17: =IF(R17=0,"لم يبدأ / Not Started",IF(R17>=1,"مكتمل / Complete","قيد التنفيذ / In Progress")) -> لم يبدأ / Not Started | T17: =IF(R17>=1,"مكتمل / Complete",IF(L17<17,"أكمل البيانات الأساسية / Complete core planning fields",IF(M17<4,"أكمل التمايز / Complete differentiation",IF(N17<9,"أكمل الحصة الأولى / Complete First Period",IF(O17<9,"أكمل الحصة الثانية / Complete Second Period","أكمل تأمل المعلم / Complete teacher reflection"))))) -> أكمل البيانات الأساسية / Complete core planning fields
A18: 17 | B18: =IF('WEEK 17'!C2="","",'WEEK 17'!C2) | C18: =IF('WEEK 17'!I2="","",'WEEK 17'!I2) | D18: =IF('WEEK 17'!C3="","",'WEEK 17'!C3) | E18: =IF('WEEK 17'!I3="","",'WEEK 17'!I3) | F18: =IF('WEEK 17'!C5="","",'WEEK 17'!C5) | G18: =IF('WEEK 17'!C6="","",'WEEK 17'!C6) | H18: =IF('WEEK 17'!C8="","",'WEEK 17'!C8) | I18: =IF('WEEK 17'!A10="","",'WEEK 17'!A10) | J18: =IF('WEEK 17'!C7="","",'WEEK 17'!C7) | K18: =IF('WEEK 17'!I7="","",'WEEK 17'!I7) | L18: =--('WEEK 17'!C2<>"")+--('WEEK 17'!I2<>"")+--('WEEK 17'!C3<>"")+--('WEEK 17'!I3<>"")+--('WEEK 17'!C4<>"")+--('WEEK 17'!I4<>"")+--('WEEK 17'!C5<>"")+--('WEEK 17'!C6<>"")+--('WEEK 17'!C7<>"")+--('WEEK 17'!I7<>"")+--('WEEK 17'!C8<>"")+--('WEEK 17'!A10<>"")+--('WEEK 17'!D10<>"")+--('WEEK 17'!H10<>"")+--(COUNTA('WEEK 17'!A12:D12)>0)+--('WEEK 17'!E12<>"")+--('WEEK 17'!H12<>"") -> 0 | M18: =--(LEN('WEEK 17'!B14)>LEN(LISTS!$Q$2))+--(LEN('WEEK 17'!D14)>LEN(LISTS!$Q$2))+--(LEN('WEEK 17'!F14)>LEN(LISTS!$Q$2))+--(LEN('WEEK 17'!H14)>LEN(LISTS!$Q$2)) -> 0 | N18: =--('WEEK 17'!B17<>"")+--('WEEK 17'!B18<>"")+--('WEEK 17'!B19<>"")+--('WEEK 17'!B20<>"")+--('WEEK 17'!B21<>"")+--(LEN('WEEK 17'!B22)>LEN(LISTS!$P$2))+--('WEEK 17'!B23<>"")+--('WEEK 17'!B24<>"")+--('WEEK 17'!B25<>"") -> 0 | O18: =--('WEEK 17'!G17<>"")+--('WEEK 17'!G18<>"")+--('WEEK 17'!G19<>"")+--('WEEK 17'!G20<>"")+--('WEEK 17'!G21<>"")+--(LEN('WEEK 17'!G22)>LEN(LISTS!$P$2))+--('WEEK 17'!G23<>"")+--('WEEK 17'!G24<>"")+--('WEEK 17'!G25<>"") -> 0 | P18: =--(LEN('WEEK 17'!B26)>LEN(LISTS!$R$2)) -> 0 | Q18: =SUM(L18:P18) -> 0 | R18: =Q18/40 -> 0 | S18: =IF(R18=0,"لم يبدأ / Not Started",IF(R18>=1,"مكتمل / Complete","قيد التنفيذ / In Progress")) -> لم يبدأ / Not Started | T18: =IF(R18>=1,"مكتمل / Complete",IF(L18<17,"أكمل البيانات الأساسية / Complete core planning fields",IF(M18<4,"أكمل التمايز / Complete differentiation",IF(N18<9,"أكمل الحصة الأولى / Complete First Period",IF(O18<9,"أكمل الحصة الثانية / Complete Second Period","أكمل تأمل المعلم / Complete teacher reflection"))))) -> أكمل البيانات الأساسية / Complete core planning fields
A19: 18 | B19: =IF('WEEK 18'!C2="","",'WEEK 18'!C2) | C19: =IF('WEEK 18'!I2="","",'WEEK 18'!I2) | D19: =IF('WEEK 18'!C3="","",'WEEK 18'!C3) | E19: =IF('WEEK 18'!I3="","",'WEEK 18'!I3) | F19: =IF('WEEK 18'!C5="","",'WEEK 18'!C5) | G19: =IF('WEEK 18'!C6="","",'WEEK 18'!C6) | H19: =IF('WEEK 18'!C8="","",'WEEK 18'!C8) | I19: =IF('WEEK 18'!A10="","",'WEEK 18'!A10) | J19: =IF('WEEK 18'!C7="","",'WEEK 18'!C7) | K19: =IF('WEEK 18'!I7="","",'WEEK 18'!I7) | L19: =--('WEEK 18'!C2<>"")+--('WEEK 18'!I2<>"")+--('WEEK 18'!C3<>"")+--('WEEK 18'!I3<>"")+--('WEEK 18'!C4<>"")+--('WEEK 18'!I4<>"")+--('WEEK 18'!C5<>"")+--('WEEK 18'!C6<>"")+--('WEEK 18'!C7<>"")+--('WEEK 18'!I7<>"")+--('WEEK 18'!C8<>"")+--('WEEK 18'!A10<>"")+--('WEEK 18'!D10<>"")+--('WEEK 18'!H10<>"")+--(COUNTA('WEEK 18'!A12:D12)>0)+--('WEEK 18'!E12<>"")+--('WEEK 18'!H12<>"") -> 0 | M19: =--(LEN('WEEK 18'!B14)>LEN(LISTS!$Q$2))+--(LEN('WEEK 18'!D14)>LEN(LISTS!$Q$2))+--(LEN('WEEK 18'!F14)>LEN(LISTS!$Q$2))+--(LEN('WEEK 18'!H14)>LEN(LISTS!$Q$2)) -> 0 | N19: =--('WEEK 18'!B17<>"")+--('WEEK 18'!B18<>"")+--('WEEK 18'!B19<>"")+--('WEEK 18'!B20<>"")+--('WEEK 18'!B21<>"")+--(LEN('WEEK 18'!B22)>LEN(LISTS!$P$2))+--('WEEK 18'!B23<>"")+--('WEEK 18'!B24<>"")+--('WEEK 18'!B25<>"") -> 0 | O19: =--('WEEK 18'!G17<>"")+--('WEEK 18'!G18<>"")+--('WEEK 18'!G19<>"")+--('WEEK 18'!G20<>"")+--('WEEK 18'!G21<>"")+--(LEN('WEEK 18'!G22)>LEN(LISTS!$P$2))+--('WEEK 18'!G23<>"")+--('WEEK 18'!G24<>"")+--('WEEK 18'!G25<>"") -> 0 | P19: =--(LEN('WEEK 18'!B26)>LEN(LISTS!$R$2)) -> 0 | Q19: =SUM(L19:P19) -> 0 | R19: =Q19/40 -> 0 | S19: =IF(R19=0,"لم يبدأ / Not Started",IF(R19>=1,"مكتمل / Complete","قيد التنفيذ / In Progress")) -> لم يبدأ / Not Started | T19: =IF(R19>=1,"مكتمل / Complete",IF(L19<17,"أكمل البيانات الأساسية / Complete core planning fields",IF(M19<4,"أكمل التمايز / Complete differentiation",IF(N19<9,"أكمل الحصة الأولى / Complete First Period",IF(O19<9,"أكمل الحصة الثانية / Complete Second Period","أكمل تأمل المعلم / Complete teacher reflection"))))) -> أكمل البيانات الأساسية / Complete core planning fields
A20: 19 | B20: =IF('WEEK 19'!C2="","",'WEEK 19'!C2) | C20: =IF('WEEK 19'!I2="","",'WEEK 19'!I2) | D20: =IF('WEEK 19'!C3="","",'WEEK 19'!C3) | E20: =IF('WEEK 19'!I3="","",'WEEK 19'!I3) | F20: =IF('WEEK 19'!C5="","",'WEEK 19'!C5) | G20: =IF('WEEK 19'!C6="","",'WEEK 19'!C6) | H20: =IF('WEEK 19'!C8="","",'WEEK 19'!C8) | I20: =IF('WEEK 19'!A10="","",'WEEK 19'!A10) | J20: =IF('WEEK 19'!C7="","",'WEEK 19'!C7) | K20: =IF('WEEK 19'!I7="","",'WEEK 19'!I7) | L20: =--('WEEK 19'!C2<>"")+--('WEEK 19'!I2<>"")+--('WEEK 19'!C3<>"")+--('WEEK 19'!I3<>"")+--('WEEK 19'!C4<>"")+--('WEEK 19'!I4<>"")+--('WEEK 19'!C5<>"")+--('WEEK 19'!C6<>"")+--('WEEK 19'!C7<>"")+--('WEEK 19'!I7<>"")+--('WEEK 19'!C8<>"")+--('WEEK 19'!A10<>"")+--('WEEK 19'!D10<>"")+--('WEEK 19'!H10<>"")+--(COUNTA('WEEK 19'!A12:D12)>0)+--('WEEK 19'!E12<>"")+--('WEEK 19'!H12<>"") -> 0 | M20: =--(LEN('WEEK 19'!B14)>LEN(LISTS!$Q$2))+--(LEN('WEEK 19'!D14)>LEN(LISTS!$Q$2))+--(LEN('WEEK 19'!F14)>LEN(LISTS!$Q$2))+--(LEN('WEEK 19'!H14)>LEN(LISTS!$Q$2)) -> 0 | N20: =--('WEEK 19'!B17<>"")+--('WEEK 19'!B18<>"")+--('WEEK 19'!B19<>"")+--('WEEK 19'!B20<>"")+--('WEEK 19'!B21<>"")+--(LEN('WEEK 19'!B22)>LEN(LISTS!$P$2))+--('WEEK 19'!B23<>"")+--('WEEK 19'!B24<>"")+--('WEEK 19'!B25<>"") -> 0 | O20: =--('WEEK 19'!G17<>"")+--('WEEK 19'!G18<>"")+--('WEEK 19'!G19<>"")+--('WEEK 19'!G20<>"")+--('WEEK 19'!G21<>"")+--(LEN('WEEK 19'!G22)>LEN(LISTS!$P$2))+--('WEEK 19'!G23<>"")+--('WEEK 19'!G24<>"")+--('WEEK 19'!G25<>"") -> 0 | P20: =--(LEN('WEEK 19'!B26)>LEN(LISTS!$R$2)) -> 0 | Q20: =SUM(L20:P20) -> 0 | R20: =Q20/40 -> 0 | S20: =IF(R20=0,"لم يبدأ / Not Started",IF(R20>=1,"مكتمل / Complete","قيد التنفيذ / In Progress")) -> لم يبدأ / Not Started | T20: =IF(R20>=1,"مكتمل / Complete",IF(L20<17,"أكمل البيانات الأساسية / Complete core planning fields",IF(M20<4,"أكمل التمايز / Complete differentiation",IF(N20<9,"أكمل الحصة الأولى / Complete First Period",IF(O20<9,"أكمل الحصة الثانية / Complete Second Period","أكمل تأمل المعلم / Complete teacher reflection"))))) -> أكمل البيانات الأساسية / Complete core planning fields
A21: 20 | B21: =IF('WEEK 20'!C2="","",'WEEK 20'!C2) | C21: =IF('WEEK 20'!I2="","",'WEEK 20'!I2) | D21: =IF('WEEK 20'!C3="","",'WEEK 20'!C3) | E21: =IF('WEEK 20'!I3="","",'WEEK 20'!I3) | F21: =IF('WEEK 20'!C5="","",'WEEK 20'!C5) | G21: =IF('WEEK 20'!C6="","",'WEEK 20'!C6) | H21: =IF('WEEK 20'!C8="","",'WEEK 20'!C8) | I21: =IF('WEEK 20'!A10="","",'WEEK 20'!A10) | J21: =IF('WEEK 20'!C7="","",'WEEK 20'!C7) | K21: =IF('WEEK 20'!I7="","",'WEEK 20'!I7) | L21: =--('WEEK 20'!C2<>"")+--('WEEK 20'!I2<>"")+--('WEEK 20'!C3<>"")+--('WEEK 20'!I3<>"")+--('WEEK 20'!C4<>"")+--('WEEK 20'!I4<>"")+--('WEEK 20'!C5<>"")+--('WEEK 20'!C6<>"")+--('WEEK 20'!C7<>"")+--('WEEK 20'!I7<>"")+--('WEEK 20'!C8<>"")+--('WEEK 20'!A10<>"")+--('WEEK 20'!D10<>"")+--('WEEK 20'!H10<>"")+--(COUNTA('WEEK 20'!A12:D12)>0)+--('WEEK 20'!E12<>"")+--('WEEK 20'!H12<>"") -> 0 | M21: =--(LEN('WEEK 20'!B14)>LEN(LISTS!$Q$2))+--(LEN('WEEK 20'!D14)>LEN(LISTS!$Q$2))+--(LEN('WEEK 20'!F14)>LEN(LISTS!$Q$2))+--(LEN('WEEK 20'!H14)>LEN(LISTS!$Q$2)) -> 0 | N21: =--('WEEK 20'!B17<>"")+--('WEEK 20'!B18<>"")+--('WEEK 20'!B19<>"")+--('WEEK 20'!B20<>"")+--('WEEK 20'!B21<>"")+--(LEN('WEEK 20'!B22)>LEN(LISTS!$P$2))+--('WEEK 20'!B23<>"")+--('WEEK 20'!B24<>"")+--('WEEK 20'!B25<>"") -> 0 | O21: =--('WEEK 20'!G17<>"")+--('WEEK 20'!G18<>"")+--('WEEK 20'!G19<>"")+--('WEEK 20'!G20<>"")+--('WEEK 20'!G21<>"")+--(LEN('WEEK 20'!G22)>LEN(LISTS!$P$2))+--('WEEK 20'!G23<>"")+--('WEEK 20'!G24<>"")+--('WEEK 20'!G25<>"") -> 0 | P21: =--(LEN('WEEK 20'!B26)>LEN(LISTS!$R$2)) -> 0 | Q21: =SUM(L21:P21) -> 0 | R21: =Q21/40 -> 0 | S21: =IF(R21=0,"لم يبدأ / Not Started",IF(R21>=1,"مكتمل / Complete","قيد التنفيذ / In Progress")) -> لم يبدأ / Not Started | T21: =IF(R21>=1,"مكتمل / Complete",IF(L21<17,"أكمل البيانات الأساسية / Complete core planning fields",IF(M21<4,"أكمل التمايز / Complete differentiation",IF(N21<9,"أكمل الحصة الأولى / Complete First Period",IF(O21<9,"أكمل الحصة الثانية / Complete Second Period","أكمل تأمل المعلم / Complete teacher reflection"))))) -> أكمل البيانات الأساسية / Complete core planning fields
A22: 21 | B22: =IF('WEEK 21'!C2="","",'WEEK 21'!C2) | C22: =IF('WEEK 21'!I2="","",'WEEK 21'!I2) | D22: =IF('WEEK 21'!C3="","",'WEEK 21'!C3) | E22: =IF('WEEK 21'!I3="","",'WEEK 21'!I3) | F22: =IF('WEEK 21'!C5="","",'WEEK 21'!C5) | G22: =IF('WEEK 21'!C6="","",'WEEK 21'!C6) | H22: =IF('WEEK 21'!C8="","",'WEEK 21'!C8) | I22: =IF('WEEK 21'!A10="","",'WEEK 21'!A10) | J22: =IF('WEEK 21'!C7="","",'WEEK 21'!C7) | K22: =IF('WEEK 21'!I7="","",'WEEK 21'!I7) | L22: =--('WEEK 21'!C2<>"")+--('WEEK 21'!I2<>"")+--('WEEK 21'!C3<>"")+--('WEEK 21'!I3<>"")+--('WEEK 21'!C4<>"")+--('WEEK 21'!I4<>"")+--('WEEK 21'!C5<>"")+--('WEEK 21'!C6<>"")+--('WEEK 21'!C7<>"")+--('WEEK 21'!I7<>"")+--('WEEK 21'!C8<>"")+--('WEEK 21'!A10<>"")+--('WEEK 21'!D10<>"")+--('WEEK 21'!H10<>"")+--(COUNTA('WEEK 21'!A12:D12)>0)+--('WEEK 21'!E12<>"")+--('WEEK 21'!H12<>"") -> 0 | M22: =--(LEN('WEEK 21'!B14)>LEN(LISTS!$Q$2))+--(LEN('WEEK 21'!D14)>LEN(LISTS!$Q$2))+--(LEN('WEEK 21'!F14)>LEN(LISTS!$Q$2))+--(LEN('WEEK 21'!H14)>LEN(LISTS!$Q$2)) -> 0 | N22: =--('WEEK 21'!B17<>"")+--('WEEK 21'!B18<>"")+--('WEEK 21'!B19<>"")+--('WEEK 21'!B20<>"")+--('WEEK 21'!B21<>"")+--(LEN('WEEK 21'!B22)>LEN(LISTS!$P$2))+--('WEEK 21'!B23<>"")+--('WEEK 21'!B24<>"")+--('WEEK 21'!B25<>"") -> 0 | O22: =--('WEEK 21'!G17<>"")+--('WEEK 21'!G18<>"")+--('WEEK 21'!G19<>"")+--('WEEK 21'!G20<>"")+--('WEEK 21'!G21<>"")+--(LEN('WEEK 21'!G22)>LEN(LISTS!$P$2))+--('WEEK 21'!G23<>"")+--('WEEK 21'!G24<>"")+--('WEEK 21'!G25<>"") -> 0 | P22: =--(LEN('WEEK 21'!B26)>LEN(LISTS!$R$2)) -> 0 | Q22: =SUM(L22:P22) -> 0 | R22: =Q22/40 -> 0 | S22: =IF(R22=0,"لم يبدأ / Not Started",IF(R22>=1,"مكتمل / Complete","قيد التنفيذ / In Progress")) -> لم يبدأ / Not Started | T22: =IF(R22>=1,"مكتمل / Complete",IF(L22<17,"أكمل البيانات الأساسية / Complete core planning fields",IF(M22<4,"أكمل التمايز / Complete differentiation",IF(N22<9,"أكمل الحصة الأولى / Complete First Period",IF(O22<9,"أكمل الحصة الثانية / Complete Second Period","أكمل تأمل المعلم / Complete teacher reflection"))))) -> أكمل البيانات الأساسية / Complete core planning fields
A23: 22 | B23: =IF('WEEK 22'!C2="","",'WEEK 22'!C2) | C23: =IF('WEEK 22'!I2="","",'WEEK 22'!I2) | D23: =IF('WEEK 22'!C3="","",'WEEK 22'!C3) | E23: =IF('WEEK 22'!I3="","",'WEEK 22'!I3) | F23: =IF('WEEK 22'!C5="","",'WEEK 22'!C5) | G23: =IF('WEEK 22'!C6="","",'WEEK 22'!C6) | H23: =IF('WEEK 22'!C8="","",'WEEK 22'!C8) | I23: =IF('WEEK 22'!A10="","",'WEEK 22'!A10) | J23: =IF('WEEK 22'!C7="","",'WEEK 22'!C7) | K23: =IF('WEEK 22'!I7="","",'WEEK 22'!I7) | L23: =--('WEEK 22'!C2<>"")+--('WEEK 22'!I2<>"")+--('WEEK 22'!C3<>"")+--('WEEK 22'!I3<>"")+--('WEEK 22'!C4<>"")+--('WEEK 22'!I4<>"")+--('WEEK 22'!C5<>"")+--('WEEK 22'!C6<>"")+--('WEEK 22'!C7<>"")+--('WEEK 22'!I7<>"")+--('WEEK 22'!C8<>"")+--('WEEK 22'!A10<>"")+--('WEEK 22'!D10<>"")+--('WEEK 22'!H10<>"")+--(COUNTA('WEEK 22'!A12:D12)>0)+--('WEEK 22'!E12<>"")+--('WEEK 22'!H12<>"") -> 0 | M23: =--(LEN('WEEK 22'!B14)>LEN(LISTS!$Q$2))+--(LEN('WEEK 22'!D14)>LEN(LISTS!$Q$2))+--(LEN('WEEK 22'!F14)>LEN(LISTS!$Q$2))+--(LEN('WEEK 22'!H14)>LEN(LISTS!$Q$2)) -> 0 | N23: =--('WEEK 22'!B17<>"")+--('WEEK 22'!B18<>"")+--('WEEK 22'!B19<>"")+--('WEEK 22'!B20<>"")+--('WEEK 22'!B21<>"")+--(LEN('WEEK 22'!B22)>LEN(LISTS!$P$2))+--('WEEK 22'!B23<>"")+--('WEEK 22'!B24<>"")+--('WEEK 22'!B25<>"") -> 0 | O23: =--('WEEK 22'!G17<>"")+--('WEEK 22'!G18<>"")+--('WEEK 22'!G19<>"")+--('WEEK 22'!G20<>"")+--('WEEK 22'!G21<>"")+--(LEN('WEEK 22'!G22)>LEN(LISTS!$P$2))+--('WEEK 22'!G23<>"")+--('WEEK 22'!G24<>"")+--('WEEK 22'!G25<>"") -> 0 | P23: =--(LEN('WEEK 22'!B26)>LEN(LISTS!$R$2)) -> 0 | Q23: =SUM(L23:P23) -> 0 | R23: =Q23/40 -> 0 | S23: =IF(R23=0,"لم يبدأ / Not Started",IF(R23>=1,"مكتمل / Complete","قيد التنفيذ / In Progress")) -> لم يبدأ / Not Started | T23: =IF(R23>=1,"مكتمل / Complete",IF(L23<17,"أكمل البيانات الأساسية / Complete core planning fields",IF(M23<4,"أكمل التمايز / Complete differentiation",IF(N23<9,"أكمل الحصة الأولى / Complete First Period",IF(O23<9,"أكمل الحصة الثانية / Complete Second Period","أكمل تأمل المعلم / Complete teacher reflection"))))) -> أكمل البيانات الأساسية / Complete core planning fields
A24: 23 | B24: =IF('WEEK 23'!C2="","",'WEEK 23'!C2) | C24: =IF('WEEK 23'!I2="","",'WEEK 23'!I2) | D24: =IF('WEEK 23'!C3="","",'WEEK 23'!C3) | E24: =IF('WEEK 23'!I3="","",'WEEK 23'!I3) | F24: =IF('WEEK 23'!C5="","",'WEEK 23'!C5) | G24: =IF('WEEK 23'!C6="","",'WEEK 23'!C6) | H24: =IF('WEEK 23'!C8="","",'WEEK 23'!C8) | I24: =IF('WEEK 23'!A10="","",'WEEK 23'!A10) | J24: =IF('WEEK 23'!C7="","",'WEEK 23'!C7) | K24: =IF('WEEK 23'!I7="","",'WEEK 23'!I7) | L24: =--('WEEK 23'!C2<>"")+--('WEEK 23'!I2<>"")+--('WEEK 23'!C3<>"")+--('WEEK 23'!I3<>"")+--('WEEK 23'!C4<>"")+--('WEEK 23'!I4<>"")+--('WEEK 23'!C5<>"")+--('WEEK 23'!C6<>"")+--('WEEK 23'!C7<>"")+--('WEEK 23'!I7<>"")+--('WEEK 23'!C8<>"")+--('WEEK 23'!A10<>"")+--('WEEK 23'!D10<>"")+--('WEEK 23'!H10<>"")+--(COUNTA('WEEK 23'!A12:D12)>0)+--('WEEK 23'!E12<>"")+--('WEEK 23'!H12<>"") -> 0 | M24: =--(LEN('WEEK 23'!B14)>LEN(LISTS!$Q$2))+--(LEN('WEEK 23'!D14)>LEN(LISTS!$Q$2))+--(LEN('WEEK 23'!F14)>LEN(LISTS!$Q$2))+--(LEN('WEEK 23'!H14)>LEN(LISTS!$Q$2)) -> 0 | N24: =--('WEEK 23'!B17<>"")+--('WEEK 23'!B18<>"")+--('WEEK 23'!B19<>"")+--('WEEK 23'!B20<>"")+--('WEEK 23'!B21<>"")+--(LEN('WEEK 23'!B22)>LEN(LISTS!$P$2))+--('WEEK 23'!B23<>"")+--('WEEK 23'!B24<>"")+--('WEEK 23'!B25<>"") -> 0 | O24: =--('WEEK 23'!G17<>"")+--('WEEK 23'!G18<>"")+--('WEEK 23'!G19<>"")+--('WEEK 23'!G20<>"")+--('WEEK 23'!G21<>"")+--(LEN('WEEK 23'!G22)>LEN(LISTS!$P$2))+--('WEEK 23'!G23<>"")+--('WEEK 23'!G24<>"")+--('WEEK 23'!G25<>"") -> 0 | P24: =--(LEN('WEEK 23'!B26)>LEN(LISTS!$R$2)) -> 0 | Q24: =SUM(L24:P24) -> 0 | R24: =Q24/40 -> 0 | S24: =IF(R24=0,"لم يبدأ / Not Started",IF(R24>=1,"مكتمل / Complete","قيد التنفيذ / In Progress")) -> لم يبدأ / Not Started | T24: =IF(R24>=1,"مكتمل / Complete",IF(L24<17,"أكمل البيانات الأساسية / Complete core planning fields",IF(M24<4,"أكمل التمايز / Complete differentiation",IF(N24<9,"أكمل الحصة الأولى / Complete First Period",IF(O24<9,"أكمل الحصة الثانية / Complete Second Period","أكمل تأمل المعلم / Complete teacher reflection"))))) -> أكمل البيانات الأساسية / Complete core planning fields
A25: 24 | B25: =IF('WEEK 24'!C2="","",'WEEK 24'!C2) | C25: =IF('WEEK 24'!I2="","",'WEEK 24'!I2) | D25: =IF('WEEK 24'!C3="","",'WEEK 24'!C3) | E25: =IF('WEEK 24'!I3="","",'WEEK 24'!I3) | F25: =IF('WEEK 24'!C5="","",'WEEK 24'!C5) | G25: =IF('WEEK 24'!C6="","",'WEEK 24'!C6) | H25: =IF('WEEK 24'!C8="","",'WEEK 24'!C8) | I25: =IF('WEEK 24'!A10="","",'WEEK 24'!A10) | J25: =IF('WEEK 24'!C7="","",'WEEK 24'!C7) | K25: =IF('WEEK 24'!I7="","",'WEEK 24'!I7) | L25: =--('WEEK 24'!C2<>"")+--('WEEK 24'!I2<>"")+--('WEEK 24'!C3<>"")+--('WEEK 24'!I3<>"")+--('WEEK 24'!C4<>"")+--('WEEK 24'!I4<>"")+--('WEEK 24'!C5<>"")+--('WEEK 24'!C6<>"")+--('WEEK 24'!C7<>"")+--('WEEK 24'!I7<>"")+--('WEEK 24'!C8<>"")+--('WEEK 24'!A10<>"")+--('WEEK 24'!D10<>"")+--('WEEK 24'!H10<>"")+--(COUNTA('WEEK 24'!A12:D12)>0)+--('WEEK 24'!E12<>"")+--('WEEK 24'!H12<>"") -> 0 | M25: =--(LEN('WEEK 24'!B14)>LEN(LISTS!$Q$2))+--(LEN('WEEK 24'!D14)>LEN(LISTS!$Q$2))+--(LEN('WEEK 24'!F14)>LEN(LISTS!$Q$2))+--(LEN('WEEK 24'!H14)>LEN(LISTS!$Q$2)) -> 0 | N25: =--('WEEK 24'!B17<>"")+--('WEEK 24'!B18<>"")+--('WEEK 24'!B19<>"")+--('WEEK 24'!B20<>"")+--('WEEK 24'!B21<>"")+--(LEN('WEEK 24'!B22)>LEN(LISTS!$P$2))+--('WEEK 24'!B23<>"")+--('WEEK 24'!B24<>"")+--('WEEK 24'!B25<>"") -> 0 | O25: =--('WEEK 24'!G17<>"")+--('WEEK 24'!G18<>"")+--('WEEK 24'!G19<>"")+--('WEEK 24'!G20<>"")+--('WEEK 24'!G21<>"")+--(LEN('WEEK 24'!G22)>LEN(LISTS!$P$2))+--('WEEK 24'!G23<>"")+--('WEEK 24'!G24<>"")+--('WEEK 24'!G25<>"") -> 0 | P25: =--(LEN('WEEK 24'!B26)>LEN(LISTS!$R$2)) -> 0 | Q25: =SUM(L25:P25) -> 0 | R25: =Q25/40 -> 0 | S25: =IF(R25=0,"لم يبدأ / Not Started",IF(R25>=1,"مكتمل / Complete","قيد التنفيذ / In Progress")) -> لم يبدأ / Not Started | T25: =IF(R25>=1,"مكتمل / Complete",IF(L25<17,"أكمل البيانات الأساسية / Complete core planning fields",IF(M25<4,"أكمل التمايز / Complete differentiation",IF(N25<9,"أكمل الحصة الأولى / Complete First Period",IF(O25<9,"أكمل الحصة الثانية / Complete Second Period","أكمل تأمل المعلم / Complete teacher reflection"))))) -> أكمل البيانات الأساسية / Complete core planning fields
A26: 25 | B26: =IF('WEEK 25'!C2="","",'WEEK 25'!C2) | C26: =IF('WEEK 25'!I2="","",'WEEK 25'!I2) | D26: =IF('WEEK 25'!C3="","",'WEEK 25'!C3) | E26: =IF('WEEK 25'!I3="","",'WEEK 25'!I3) | F26: =IF('WEEK 25'!C5="","",'WEEK 25'!C5) | G26: =IF('WEEK 25'!C6="","",'WEEK 25'!C6) | H26: =IF('WEEK 25'!C8="","",'WEEK 25'!C8) | I26: =IF('WEEK 25'!A10="","",'WEEK 25'!A10) | J26: =IF('WEEK 25'!C7="","",'WEEK 25'!C7) | K26: =IF('WEEK 25'!I7="","",'WEEK 25'!I7) | L26: =--('WEEK 25'!C2<>"")+--('WEEK 25'!I2<>"")+--('WEEK 25'!C3<>"")+--('WEEK 25'!I3<>"")+--('WEEK 25'!C4<>"")+--('WEEK 25'!I4<>"")+--('WEEK 25'!C5<>"")+--('WEEK 25'!C6<>"")+--('WEEK 25'!C7<>"")+--('WEEK 25'!I7<>"")+--('WEEK 25'!C8<>"")+--('WEEK 25'!A10<>"")+--('WEEK 25'!D10<>"")+--('WEEK 25'!H10<>"")+--(COUNTA('WEEK 25'!A12:D12)>0)+--('WEEK 25'!E12<>"")+--('WEEK 25'!H12<>"") -> 0 | M26: =--(LEN('WEEK 25'!B14)>LEN(LISTS!$Q$2))+--(LEN('WEEK 25'!D14)>LEN(LISTS!$Q$2))+--(LEN('WEEK 25'!F14)>LEN(LISTS!$Q$2))+--(LEN('WEEK 25'!H14)>LEN(LISTS!$Q$2)) -> 0 | N26: =--('WEEK 25'!B17<>"")+--('WEEK 25'!B18<>"")+--('WEEK 25'!B19<>"")+--('WEEK 25'!B20<>"")+--('WEEK 25'!B21<>"")+--(LEN('WEEK 25'!B22)>LEN(LISTS!$P$2))+--('WEEK 25'!B23<>"")+--('WEEK 25'!B24<>"")+--('WEEK 25'!B25<>"") -> 0 | O26: =--('WEEK 25'!G17<>"")+--('WEEK 25'!G18<>"")+--('WEEK 25'!G19<>"")+--('WEEK 25'!G20<>"")+--('WEEK 25'!G21<>"")+--(LEN('WEEK 25'!G22)>LEN(LISTS!$P$2))+--('WEEK 25'!G23<>"")+--('WEEK 25'!G24<>"")+--('WEEK 25'!G25<>"") -> 0 | P26: =--(LEN('WEEK 25'!B26)>LEN(LISTS!$R$2)) -> 0 | Q26: =SUM(L26:P26) -> 0 | R26: =Q26/40 -> 0 | S26: =IF(R26=0,"لم يبدأ / Not Started",IF(R26>=1,"مكتمل / Complete","قيد التنفيذ / In Progress")) -> لم يبدأ / Not Started | T26: =IF(R26>=1,"مكتمل / Complete",IF(L26<17,"أكمل البيانات الأساسية / Complete core planning fields",IF(M26<4,"أكمل التمايز / Complete differentiation",IF(N26<9,"أكمل الحصة الأولى / Complete First Period",IF(O26<9,"أكمل الحصة الثانية / Complete Second Period","أكمل تأمل المعلم / Complete teacher reflection"))))) -> أكمل البيانات الأساسية / Complete core planning fields
